Workbook
Name Yes: 'PUX ICs'!$T$2

Sheet Definitions & Instructions
A1: Instructions:
A2: Note the most current trending rating from Aug 25, for your Employee in column L ,M, N (PLEASE DO NOT CHANGE) . Column O is pre-seeded with Aug 25 Talent Assessment Mappings and will be discussed during PUX Calibration Tues.Dec 2 , please modify based upon a combination of observations and feedback received .
A3: The columns M, N and O will auto-populate to help you decide if the performance vs the potential has been accurately plotted per the definitions.
A4: Add notes on where you need support from the discussion or if you want to call out any feedback in advance of the discussion. For example: if someone new in role has been rated Strong or Needs Focus or will be presented for a promotion
A7: Performance: Consistency and level of impact in current and past roles (Low / Medium / High).
A8: Potential: Likelihood of success in more complex or senior roles (Low / Medium / High).
A11: FY25 Talent Indicator | B11: Talent Mapping Position [Performance vs Potential] | C11: Development Focus | D11: Development Action
A12: 1. Underperforming Talent | B12: Underperforming Talent [L,L] | C12: re-assign or manage out of Alteryx | D12: Make A Plan - Identify a plan to improve performance in partnership with HR
A13: 2. Solid Talent | B13: Solid Talent [M,L] | C13: consider expanding current role, explore lateral/development opportunities | D13: Develop in Role - Identify developmental activities to continue to grow their skill and set them up for success for anticipated progression
A14: 3. Expert Talent | B14: Expert Talent [H,L] | C14: leverage experience to mentor and growth others | D14: Develop in Role - Identify developmental activities to continue to grow their skill and set them up for success for anticipated progression
A15: 4. Inconsistent Talent | B15: Inconsistent Talent [L,M] | C15: re-establish performance expectations in current role, drive performance and re-evaluate in 6-12 months | D15: Evaluate Fit/Make A Plan - Identify a coaching plan to improve performance
A16: 5. Core Talent | B16: Core Talent [M,M] | C16: identify performance barriers, explore potential to expand responsibilities in current role and discuss career aspirations (ideally for talent new in role) | D16: Develop in Role - Identify developmental activities to continue to grow their skill and set them up for success for anticipated progression
A17: 6.High Impact Talent | B17: High Impact Talent [H,M] | C17: expand responsibilities in current role, identify key experiences and increase executive exposure | D17: Differentially Invest - Ensure career discussions are happening regularly? Do they have an individual development plan? What opportunities exist to accelerate development and growth? Revist talent often to plan for next steps.
A18: 7. Emerging Talent/ Off-Track | B18: Emerging Talent /Off-track [L,H] | C18: drive performance in current role and re-evaluate in 6-12 months | D18: Evaluate Fit - What is causing them to underperform? Are they in the right role? Do they need a mentor and/or additional guidance?
A19: 8. Growth Talent | B19: Growth Talent [M,H] | C19: identify performance barriers, explore potential to expand responsibilities in current role | D19: Differentially Invest - Ensure career discussions are happening regularly? Do they have an individual development plan? What opportunities exist to accelerate development and growth? Revist talent often to plan for next steps.
A20: 9.Top Talent | B20: Top Talent [H,H] | C20: identify stretch experiences or temporary assignments, increase executive exposure | D20: Differentially Invest - Ensure career discussions are happening regularly? Do they have an individual development plan? What opportunities exist to accelerate development and growth? Revist talent often to plan for next steps.

Sheet PUX ICs
A1: Employee ID | B1: Worker | C1: Business Title | D1: Job Title | E1: Job Profile | F1: Job Level - Primary Position | G1: Hire Date | H1: Tenure Category (Months) | I1: Time in Job Profile | J1: 2023 Completed Performance Rating | K1: 2024 Completed Performance Rating | L1: Aug 2025 Talent Assessment Performance | M1: Aug 2025 Talent Assessment Potential | N1: Aug 2025 Talent Assessment 9-Box Label | O1: FY25 Talent Indicator | P1: Talent Mapping Position [Performance vs Potential] | Q1: Development Focus | R1: Development Action | S1: Notes | T1: Promotion Readiness | U1: Worker's Manager | V1: Management Chain - Level 04 | W1: Management Chain - Level 05 | X1: Management Chain - Level 06
A2: 103175 | B2: Adam Neylon | C2: Principal Product Manager | D2: Principal Product Manager | E2: Principal, Product Management-USA | F2: PT5 - Principal | G2: 44634 | H2: 3 - 5 Years | I2: 1 year(s), 10 month(s), 11 day(s) | J2: Leading | K2: Leading | L2: High | M2: High | N2: {=IF(OR(L2="",M2=""),"", IF(OR(ISNA(MATCH(L2,{"Low","Medium","High"},0)), ISNA(MATCH(M2,{"Low","Medium","High"},0))),"",_xlfn.SWITCH(L2,"Low",1,"Medium",2,"High",3) + 3 * _xlfn.SWITCH(M2,"Low",1,"Medium",2,"High",3) - 3))} -> 9 | O2: 9.Top Talent | P2: =IFERROR(VLOOKUP(O2,'Excel Table (Do Not Format)'!A:D,2,FALSE),"") -> Top Talent [H,H] | Q2: =IFERROR(VLOOKUP(O2,'Excel Table (Do Not Format)'!A:D,3,FALSE),"") -> identify stretch experiences or temporary assignments, increase executive exposure | R2: =IFERROR(VLOOKUP(O2,'Excel Table (Do Not Format)'!A:D,4,FALSE),"") -> Differentially Invest - Ensure career discussions are happening regualrly? Do they have an individual development plan? What opportunities exist to accelerate development and growth? Revisit talent often to plan for next steps. | S2: Career discussion with Laura and Lindsey in November 2025; commitment to include in Laura's team leads group and requested to join December Offsite; In current position 1yr10mo | U2: Lindsey Zibell | V2: Laura Williams Argilla | W2: Lindsey Zibell
A3: 106384 | B3: Adriana Rybarova | C3: Lead Product Designer | D3: Advanced Professional, UI/UX Designer-CZE | E3: Advanced Professional, UI/UX Designer-CZE | F3: PT4 - Advanced Professional | G3: 45966 | H3: 0 - 3 Months | I3: 0 year(s), 0 month(s), 14 day(s) | O3: 5. Core Talent | P3: =IFERROR(VLOOKUP(O3,'Excel Table (Do Not Format)'!A:D,2,FALSE),"") -> Core Talent [M,M] | Q3: =IFERROR(VLOOKUP(O3,'Excel Table (Do Not Format)'!A:D,3,FALSE),"") -> identify performance barriers, explore portential to expand responsibilties in current role and discuss career aspirations (ideally for talent new in role) | R3: =IFERROR(VLOOKUP(O3,'Excel Table (Do Not Format)'!A:D,4,FALSE),"") -> Develop in Role - Identify developmental activities to continue to grow their skill and set them up for success for anticiapted progression | S3: Just hired. | T3: No | U3: Patrik Volek | V3: Elizabeth Benker | W3: Patrik Volek
A4: 103290 | B4: Agnimitra Pathak | C4: Sr. UX Designer | D4: Sr. Professional, UI/UX Designer-IND | E4: Sr. Professional, UI/UX Designer-IND | F4: PT3 - Sr. Professional | G4: 44599 | H4: 3 - 5 Years | I4: 3 year(s), 9 month(s), 12 day(s) | J4: Solid | K4: Strong | L4: Medium | M4: High | N4: {=IF(OR(L4="",M4=""),"", IF(OR(ISNA(MATCH(L4,{"Low","Medium","High"},0)), ISNA(MATCH(M4,{"Low","Medium","High"},0))),"",_xlfn.SWITCH(L4,"Low",1,"Medium",2,"High",3) + 3 * _xlfn.SWITCH(M4,"Low",1,"Medium",2,"High",3) - 3))} -> 8 | O4: 8. Growth Talent | P4: =IFERROR(VLOOKUP(O4,'Excel Table (Do Not Format)'!A:D,2,FALSE),"") -> Growth Talent [M,H] | Q4: =IFERROR(VLOOKUP(O4,'Excel Table (Do Not Format)'!A:D,3,FALSE),"") -> identify performance barriers, explore portential to expand responsibilties in current role | R4: =IFERROR(VLOOKUP(O4,'Excel Table (Do Not Format)'!A:D,4,FALSE),"") -> Differentially Invest - Ensure career discussions are happening regualrly? Do they have an individual development plan? What opportunities exist to accelerate development and growth? Revisit talent often to plan for next steps. | S4: After the reorg, expressed clearly that he is looking for promotion and feels ready for quite some time already (in current role for 4+ years). Since then he showcased very thoughtful and proactive attitude to his projects, mentored and guided more junior members of the team. I'm confident he is ready for Lead position. | T4: Yes | U4: Patrik Volek | V4: Elizabeth Benker | W4: Patrik Volek
A5: 104817 | B5: Aida Abbasi | C5: Senior Product Designer | D5: Sr. Professional, UI/UX Designer-AUS | E5: Sr. Professional, UI/UX Designer-AUS | F5: PT3 - Sr. Professional | G5: 44942 | H5: 2 - 3 Years | I5: 2 year(s), 10 month(s), 3 day(s) | J5: Solid | K5: Strong | L5: High | M5: Medium | N5: {=IF(OR(L5="",M5=""),"", IF(OR(ISNA(MATCH(L5,{"Low","Medium","High"},0)), ISNA(MATCH(M5,{"Low","Medium","High"},0))),"",_xlfn.SWITCH(L5,"Low",1,"Medium",2,"High",3) + 3 * _xlfn.SWITCH(M5,"Low",1,"Medium",2,"High",3) - 3))} -> 6 | O5: 6.High Impact Talent | P5: =IFERROR(VLOOKUP(O5,'Excel Table (Do Not Format)'!A:D,2,FALSE),"") -> High Impact Talent [H,M] | Q5: =IFERROR(VLOOKUP(O5,'Excel Table (Do Not Format)'!A:D,3,FALSE),"") -> expand responsibilities in current role, identify key experiences and increase executive exposure | R5: =IFERROR(VLOOKUP(O5,'Excel Table (Do Not Format)'!A:D,4,FALSE),"") -> Differentially Invest - Ensure career discussions are happening regualrly? Do they have an individual development plan? What opportunities exist to accelerate development and growth? Revisit talent often to plan for next steps. | U5: Will Hurley | V5: Elizabeth Benker | W5: Will Hurley
A6: 105857 | B6: AKASH S | C6: Advanced Professional, UI/UX Designer-IND | D6: Advanced Professional, UI/UX Designer-IND | E6: Advanced Professional, UI/UX Designer-IND | F6: PT4 - Advanced Professional | G6: 45656 | H6: 10 - 12 Months | I6: 0 year(s), 3 month(s), 25 day(s) | L6: Low | M6: Medium | N6: {=IF(OR(L6="",M6=""),"", IF(OR(ISNA(MATCH(L6,{"Low","Medium","High"},0)), ISNA(MATCH(M6,{"Low","Medium","High"},0))),"",_xlfn.SWITCH(L6,"Low",1,"Medium",2,"High",3) + 3 * _xlfn.SWITCH(M6,"Low",1,"Medium",2,"High",3) - 3))} -> 4 | O6: 4. Inconsistent Talent | P6: =IFERROR(VLOOKUP(O6,'Excel Table (Do Not Format)'!A:D,2,FALSE),"") -> Inconsistent Talent [L,M] | Q6: =IFERROR(VLOOKUP(O6,'Excel Table (Do Not Format)'!A:D,3,FALSE),"") -> re-establish performance expectations in current role, drive performance and re-evaluate in 6-12 months | R6: =IFERROR(VLOOKUP(O6,'Excel Table (Do Not Format)'!A:D,4,FALSE),"") -> Evaluate Fit/Make A Plan - Identify a coaching plan to improve performance | U6: Will Hurley | V6: Elizabeth Benker | W6: Will Hurley
A7: 103874 | B7: Alexandra Zelinskaya | C7: Lead UX Researcher | D7: Advanced Professional, UI/UX Researcher-USA | E7: Advanced Professional, UI/UX Researcher-USA | F7: PT4 - Advanced Professional | G7: 44704 | H7: 3 - 5 Years | I7: 1 year(s), 1 month(s), 21 day(s) | J7: Strong | K7: Solid | L7: Medium | M7: High | N7: {=IF(OR(L7="",M7=""),"", IF(OR(ISNA(MATCH(L7,{"Low","Medium","High"},0)), ISNA(MATCH(M7,{"Low","Medium","High"},0))),"",_xlfn.SWITCH(L7,"Low",1,"Medium",2,"High",3) + 3 * _xlfn.SWITCH(M7,"Low",1,"Medium",2,"High",3) - 3))} -> 8 | O7: 5. Core Talent | P7: =IFERROR(VLOOKUP(O7,'Excel Table (Do Not Format)'!A:D,2,FALSE),"") -> Core Talent [M,M] | Q7: =IFERROR(VLOOKUP(O7,'Excel Table (Do Not Format)'!A:D,3,FALSE),"") -> identify performance barriers, explore portential to expand responsibilties in current role and discuss career aspirations (ideally for talent new in role) | R7: =IFERROR(VLOOKUP(O7,'Excel Table (Do Not Format)'!A:D,4,FALSE),"") -> Develop in Role - Identify developmental activities to continue to grow their skill and set them up for success for anticiapted progression | T7: No | U7: Olga Ziegelman | V7: Elizabeth Benker | W7: Erin Howard | X7: Olga Ziegelman
A8: 106302 | B8: Alicia Beam | C8: Lead Research Operations Specialist | D8: Advanced Professional, UI/UX Researcher-USA | E8: Advanced Professional, UI/UX Researcher-USA | F8: PT4 - Advanced Professional | G8: 45894 | H8: 0 - 3 Months | I8: 0 year(s), 2 month(s), 25 day(s) | O8: 5. Core Talent | P8: =IFERROR(VLOOKUP(O8,'Excel Table (Do Not Format)'!A:D,2,FALSE),"") -> Core Talent [M,M] | Q8: =IFERROR(VLOOKUP(O8,'Excel Table (Do Not Format)'!A:D,3,FALSE),"") -> identify performance barriers, explore portential to expand responsibilties in current role and discuss career aspirations (ideally for talent new in role) | R8: =IFERROR(VLOOKUP(O8,'Excel Table (Do Not Format)'!A:D,4,FALSE),"") -> Develop in Role - Identify developmental activities to continue to grow their skill and set them up for success for anticiapted progression | S8: Recent hire - showing high potential but too early to fully assess | T8: No | U8: Olga Ziegelman | V8: Elizabeth Benker | W8: Erin Howard | X8: Olga Ziegelman
A9: 1324 | B9: Andrew Lloyd | C9: Professional, Product Management | D9: Professional, Product Management | E9: Professional, Product Management-USA | F9: PT2 - Professional | G9: 41918 | H9: 10 - 15 Years | I9: 0 year(s), 3 month(s), 30 day(s) | J9: Solid | K9: Solid | L9: Medium | M9: Low | N9: {=IF(OR(L9="",M9=""),"", IF(OR(ISNA(MATCH(L9,{"Low","Medium","High"},0)), ISNA(MATCH(M9,{"Low","Medium","High"},0))),"",_xlfn.SWITCH(L9,"Low",1,"Medium",2,"High",3) + 3 * _xlfn.SWITCH(M9,"Low",1,"Medium",2,"High",3) - 3))} -> 2 | O9: 1. Underperforming Talent | P9: =IFERROR(VLOOKUP(O9,'Excel Table (Do Not Format)'!A:D,2,FALSE),"") -> Underperforming Talent [L,L] | Q9: =IFERROR(VLOOKUP(O9,'Excel Table (Do Not Format)'!A:D,3,FALSE),"") -> re-assign or manage out of Alteryx | R9: =IFERROR(VLOOKUP(O9,'Excel Table (Do Not Format)'!A:D,4,FALSE),"") -> Make A Plan - Identify a plan to improve performance in partnership with HR | S9: Andrew has improved, but it has not been self led and it has been slow velocity and lacking accountability, need tomove him to low performance making him in group 1 - underperforming talent | T9: No | U9: Lindsey Zibell | V9: Laura Williams Argilla | W9: Lindsey Zibell
A10: 105874 | B10: Apurva Mathur | C10: Technical Writer | D10: Professional, Technical Writer-IND | E10: Professional, Technical Writer-IND | F10: PT2 - Professional | G10: 45698 | H10: 7 - 9 Months | I10: 0 year(s), 9 month(s), 9 day(s) | L10: Medium | M10: Medium | N10: {=IF(OR(L10="",M10=""),"", IF(OR(ISNA(MATCH(L10,{"Low","Medium","High"},0)), ISNA(MATCH(M10,{"Low","Medium","High"},0))),"",_xlfn.SWITCH(L10,"Low",1,"Medium",2,"High",3) + 3 * _xlfn.SWITCH(M10,"Low",1,"Medium",2,"High",3) - 3))} -> 5 | O10: 5. Core Talent | P10: =IFERROR(VLOOKUP(O10,'Excel Table (Do Not Format)'!A:D,2,FALSE),"") -> Core Talent [M,M] | Q10: =IFERROR(VLOOKUP(O10,'Excel Table (Do Not Format)'!A:D,3,FALSE),"") -> identify performance barriers, explore portential to expand responsibilties in current role and discuss career aspirations (ideally for talent new in role) | R10: =IFERROR(VLOOKUP(O10,'Excel Table (Do Not Format)'!A:D,4,FALSE),"") -> Develop in Role - Identify developmental activities to continue to grow their skill and set them up for success for anticiapted progression | U10: Marcela Abrach | V10: Elizabeth Benker | W10: Marcela Abrach
A11: 105886 | B11: ARPIT VERMA | C11: Senior Product Designer | D11: Sr. Professional, UI/UX Designer-IND | E11: Sr. Professional, UI/UX Designer-IND | F11: PT3 - Sr. Professional | G11: 45656 | H11: 10 - 12 Months | I11: 0 year(s), 10 month(s), 20 day(s) | L11: Medium | M11: Medium | N11: {=IF(OR(L11="",M11=""),"", IF(OR(ISNA(MATCH(L11,{"Low","Medium","High"},0)), ISNA(MATCH(M11,{"Low","Medium","High"},0))),"",_xlfn.SWITCH(L11,"Low",1,"Medium",2,"High",3) + 3 * _xlfn.SWITCH(M11,"Low",1,"Medium",2,"High",3) - 3))} -> 5 | O11: 5. Core Talent | P11: =IFERROR(VLOOKUP(O11,'Excel Table (Do Not Format)'!A:D,2,FALSE),"") -> Core Talent [M,M] | Q11: =IFERROR(VLOOKUP(O11,'Excel Table (Do Not Format)'!A:D,3,FALSE),"") -> identify performance barriers, explore portential to expand responsibilties in current role and discuss career aspirations (ideally for talent new in role) | R11: =IFERROR(VLOOKUP(O11,'Excel Table (Do Not Format)'!A:D,4,FALSE),"") -> Develop in Role - Identify developmental activities to continue to grow their skill and set them up for success for anticiapted progression | U11: Will Hurley | V11: Elizabeth Benker | W11: Will Hurley
A12: 101560 | B12: Artem Pakhomov (Артём Пахомов) | C12: Professional, Product Management-UKR | D12: Professional, Product Management-UKR | E12: Professional, Product Management-UKR | F12: PT2 - Professional | G12: 44180 | H12: 3 - 5 Years | I12: 0 year(s), 0 month(s), 18 day(s) | J12: Solid | K12: Strong | L12: Medium | M12: Medium | N12: {=IF(OR(L12="",M12=""),"", IF(OR(ISNA(MATCH(L12,{"Low","Medium","High"},0)), ISNA(MATCH(M12,{"Low","Medium","High"},0))),"",_xlfn.SWITCH(L12,"Low",1,"Medium",2,"High",3) + 3 * _xlfn.SWITCH(M12,"Low",1,"Medium",2,"High",3) - 3))} -> 5 | O12: 9.Top Talent | P12: =IFERROR(VLOOKUP(O12,'Excel Table (Do Not Format)'!A:D,2,FALSE),"") -> Top Talent [H,H] | Q12: =IFERROR(VLOOKUP(O12,'Excel Table (Do Not Format)'!A:D,3,FALSE),"") -> identify stretch experiences or temporary assignments, increase executive exposure | R12: =IFERROR(VLOOKUP(O12,'Excel Table (Do Not Format)'!A:D,4,FALSE),"") -> Differentially Invest - Ensure career discussions are happening regualrly? Do they have an individual development plan? What opportunities exist to accelerate development and growth? Revisit talent often to plan for next steps. | S12: Time in Job Profile reflects title change from TPM to PM in November, and is not indicative of an actual recent job change. Has been in current role for almost 5 years. Francois is currently the manager but Nicole will complete talent mapping/performance reviews for 2026 Indicating promotion readiness - has been operating at a Sr. PM level for some time, taking ownership of a diverse range of issues and taking initiative on the newly formed Cloud Native team to address gaps and ensure projects continue moving forward even in the midst of change. His presence when reaching out to and speaking with customers is excellent, and he has been proactive in working with the CN team to align on various process changes and documentation requirements. Will be working on getting Artem more visibility across the org as a Sr. PM, and to continue focusing on the big picture and broader strategic thinking. | T12: Yes | U12: Nicole Johnson (Francois Planet) | V12: Laura Williams Argilla | W12: Nicole Johnson
A13: 105905 | B13: Ashutosh Kumar | C13: Associate Data Analyst | D13: Associate Professional, Technical Product Management-IND | E13: Associate Professional, Technical Product Management-IND | F13: PT1 - Associate Professional | G13: 45663 | H13: 10 - 12 Months | I13: 0 year(s), 4 month(s), 18 day(s) | L13: Medium | M13: Medium | N13: {=IF(OR(L13="",M13=""),"", IF(OR(ISNA(MATCH(L13,{"Low","Medium","High"},0)), ISNA(MATCH(M13,{"Low","Medium","High"},0))),"",_xlfn.SWITCH(L13,"Low",1,"Medium",2,"High",3) + 3 * _xlfn.SWITCH(M13,"Low",1,"Medium",2,"High",3) - 3))} -> 5 | O13: 5. Core Talent | P13: =IFERROR(VLOOKUP(O13,'Excel Table (Do Not Format)'!A:D,2,FALSE),"") -> Core Talent [M,M] | Q13: =IFERROR(VLOOKUP(O13,'Excel Table (Do Not Format)'!A:D,3,FALSE),"") -> identify performance barriers, explore portential to expand responsibilties in current role and discuss career aspirations (ideally for talent new in role) | R13: =IFERROR(VLOOKUP(O13,'Excel Table (Do Not Format)'!A:D,4,FALSE),"") -> Develop in Role - Identify developmental activities to continue to grow their skill and set them up for success for anticiapted progression | U13: Hitesh Bakutra | V13: Elizabeth Benker | W13: Erin Howard | X13: Hitesh Bakutra
A14: 103538 | B14: Baneen Bryan | C14: Product Designer | D14: Professional, UI/UX Designer-USA | E14: Professional, UI/UX Designer-USA | F14: PT2 - Professional | G14: 45922 | H14: 0 - 3 Months | I14: 0 year(s), 1 month(s), 28 day(s) | J14: Strong | O14: 5. Core Talent | P14: =IFERROR(VLOOKUP(O14,'Excel Table (Do Not Format)'!A:D,2,FALSE),"") -> Core Talent [M,M] | Q14: =IFERROR(VLOOKUP(O14,'Excel Table (Do Not Format)'!A:D,3,FALSE),"") -> identify performance barriers, explore portential to expand responsibilties in current role and discuss career aspirations (ideally for talent new in role) | R14: =IFERROR(VLOOKUP(O14,'Excel Table (Do Not Format)'!A:D,4,FALSE),"") -> Develop in Role - Identify developmental activities to continue to grow their skill and set them up for success for anticiapted progression | U14: Yujia Zhao | V14: Elizabeth Benker | W14: Yujia Zhao
A15: 102092 | B15: Becca Lemmons (On Leave) | C15: Principal Product Manager | D15: Principal Product Manager | E15: Principal, Product Management-USA | F15: PT5 - Principal | G15: 44389 | H15: 3 - 5 Years | I15: 0 year(s), 5 month(s), 11 day(s) | J15: Strong | K15: Leading | L15: Low | M15: Low | N15: {=IF(OR(L15="",M15=""),"", IF(OR(ISNA(MATCH(L15,{"Low","Medium","High"},0)), ISNA(MATCH(M15,{"Low","Medium","High"},0))),"",_xlfn.SWITCH(L15,"Low",1,"Medium",2,"High",3) + 3 * _xlfn.SWITCH(M15,"Low",1,"Medium",2,"High",3) - 3))} -> 1 | O15: 1. Underperforming Talent | P15: =IFERROR(VLOOKUP(O15,'Excel Table (Do Not Format)'!A:D,2,FALSE),"") -> Underperforming Talent [L,L] | Q15: =IFERROR(VLOOKUP(O15,'Excel Table (Do Not Format)'!A:D,3,FALSE),"") -> re-assign or manage out of Alteryx | R15: =IFERROR(VLOOKUP(O15,'Excel Table (Do Not Format)'!A:D,4,FALSE),"") -> Make A Plan - Identify a plan to improve performance in partnership with HR | U15: Chad Thompson | V15: Chad Thompson | W15: Chad Thompson
A16: 106400 | B16: Bob Fraser | C16: Principal Product Manager | D16: Principal, Product Management-GBR | E16: Principal, Product Management-GBR | F16: PT5 - Principal | G16: 45964 | H16: 0 - 3 Months | I16: 0 year(s), 0 month(s), 16 day(s) | O16: 5. Core Talent | P16: =IFERROR(VLOOKUP(O16,'Excel Table (Do Not Format)'!A:D,2,FALSE),"") -> Core Talent [M,M] | Q16: =IFERROR(VLOOKUP(O16,'Excel Table (Do Not Format)'!A:D,3,FALSE),"") -> identify performance barriers, explore portential to expand responsibilties in current role and discuss career aspirations (ideally for talent new in role) | R16: =IFERROR(VLOOKUP(O16,'Excel Table (Do Not Format)'!A:D,4,FALSE),"") -> Develop in Role - Identify developmental activities to continue to grow their skill and set them up for success for anticiapted progression | U16: Tomáš Mitana | V16: Chad Thompson | W16: Tomáš Mitana
A17: 104466 | B17: Brad Shaw | C17: Lead Product Manager | D17: Advanced Professional, Product Management-AUS | E17: Advanced Professional, Product Management-AUS | F17: PT4 - Advanced Professional | G17: 44823 | H17: 3 - 5 Years | I17: 1 year(s), 2 month(s), 18 day(s) | J17: Strong | K17: Strong | L17: High | M17: High | N17: {=IF(OR(L17="",M17=""),"", IF(OR(ISNA(MATCH(L17,{"Low","Medium","High"},0)), ISNA(MATCH(M17,{"Low","Medium","High"},0))),"",_xlfn.SWITCH(L17,"Low",1,"Medium",2,"High",3) + 3 * _xlfn.SWITCH(M17,"Low",1,"Medium",2,"High",3) - 3))} -> 9 | O17: 9.Top Talent | P17: =IFERROR(VLOOKUP(O17,'Excel Table (Do Not Format)'!A:D,2,FALSE),"") -> Top Talent [H,H] | Q17: =IFERROR(VLOOKUP(O17,'Excel Table (Do Not Format)'!A:D,3,FALSE),"") -> identify stretch experiences or temporary assignments, increase executive exposure | R17: =IFERROR(VLOOKUP(O17,'Excel Table (Do Not Format)'!A:D,4,FALSE),"") -> Differentially Invest - Ensure career discussions are happening regualrly? Do they have an individual development plan? What opportunities exist to accelerate development and growth? Revisit talent often to plan for next steps. | U17: Robert D'Arrigo | V17: Chad Thompson | W17: Robert D'Arrigo
A18: 102042 | B18: Bryan Chan | C18: Professional, Product Management-USA | D18: Professional, Product Management-USA | E18: Professional, Product Management-USA | F18: PT2 - Professional | G18: 44760 | H18: 3 - 5 Years | I18: 1 year(s), 8 month(s), 16 day(s) | J18: Strong | K18: Solid | L18: High | M18: High | N18: {=IF(OR(L18="",M18=""),"", IF(OR(ISNA(MATCH(L18,{"Low","Medium","High"},0)), ISNA(MATCH(M18,{"Low","Medium","High"},0))),"",_xlfn.SWITCH(L18,"Low",1,"Medium",2,"High",3) + 3 * _xlfn.SWITCH(M18,"Low",1,"Medium",2,"High",3) - 3))} -> 9 | O18: 8. Growth Talent | P18: =IFERROR(VLOOKUP(O18,'Excel Table (Do Not Format)'!A:D,2,FALSE),"") -> Growth Talent [M,H] | Q18: =IFERROR(VLOOKUP(O18,'Excel Table (Do Not Format)'!A:D,3,FALSE),"") -> identify performance barriers, explore portential to expand responsibilties in current role | R18: =IFERROR(VLOOKUP(O18,'Excel Table (Do Not Format)'!A:D,4,FALSE),"") -> Differentially Invest - Ensure career discussions are happening regualrly? Do they have an individual development plan? What opportunities exist to accelerate development and growth? Revisit talent often to plan for next steps. | S18: Identified strengths and weaknesses at October Check In, needs significantly more exposure. Wrote a Plans vision strategy, need to get it presented. Could use a wider scope. | T18: No | U18: Lindsey Zibell | V18: Laura Williams Argilla | W18: Lindsey Zibell
A19: 2298 | B19: Bryce Laird | C19: Sr. Principal, Product Management-USA | D19: Sr. Principal, Product Management-USA | E19: Sr. Principal, Product Management-USA | F19: PT6 - Sr. Principal | G19: 43402 | H19: 5 - 10 Years | I19: 0 year(s), 2 month(s), 18 day(s) | J19: Leading | K19: Leading | L19: High | M19: High | N19: {=IF(OR(L19="",M19=""),"", IF(OR(ISNA(MATCH(L19,{"Low","Medium","High"},0)), ISNA(MATCH(M19,{"Low","Medium","High"},0))),"",_xlfn.SWITCH(L19,"Low",1,"Medium",2,"High",3) + 3 * _xlfn.SWITCH(M19,"Low",1,"Medium",2,"High",3) - 3))} -> 9 | O19: 9.Top Talent | P19: =IFERROR(VLOOKUP(O19,'Excel Table (Do Not Format)'!A:D,2,FALSE),"") -> Top Talent [H,H] | Q19: =IFERROR(VLOOKUP(O19,'Excel Table (Do Not Format)'!A:D,3,FALSE),"") -> identify stretch experiences or temporary assignments, increase executive exposure | R19: =IFERROR(VLOOKUP(O19,'Excel Table (Do Not Format)'!A:D,4,FALSE),"") -> Differentially Invest - Ensure career discussions are happening regualrly? Do they have an individual development plan? What opportunities exist to accelerate development and growth? Revisit talent often to plan for next steps. | U19: Chad Thompson | V19: Chad Thompson
A20: 101375 | B20: Charles Ash | C20: Product Designer | D20: Professional, UI/UX Designer-USA | E20: Professional, UI/UX Designer-USA | F20: PT2 - Professional | G20: 43962 | H20: 5 - 10 Years | I20: 4 year(s), 10 month(s), 18 day(s) | J20: Strong | K20: Strong | L20: Low | M20: Low | N20: {=IF(OR(L20="",M20=""),"", IF(OR(ISNA(MATCH(L20,{"Low","Medium","High"},0)), ISNA(MATCH(M20,{"Low","Medium","High"},0))),"",_xlfn.SWITCH(L20,"Low",1,"Medium",2,"High",3) + 3 * _xlfn.SWITCH(M20,"Low",1,"Medium",2,"High",3) - 3))} -> 1 | O20: 2. Solid Talent | P20: =IFERROR(VLOOKUP(O20,'Excel Table (Do Not Format)'!A:D,2,FALSE),"") -> Solid Talent [M,L] | Q20: =IFERROR(VLOOKUP(O20,'Excel Table (Do Not Format)'!A:D,3,FALSE),"") -> consider expanding current role, explore lateral/development opportunities | R20: =IFERROR(VLOOKUP(O20,'Excel Table (Do Not Format)'!A:D,4,FALSE),"") -> Develop in Role - Identify developmental activities to continue to grow their skill and set them up for success for anticiapted progression | S20: Can produce solid designs against the requirements on time. Need to be more proactive. | T20: No | U20: Yujia Zhao | V20: Elizabeth Benker | W20: Yujia Zhao
A21: 103231 | B21: Chirag Dadheech | C21: Lead Product Insight Analyst | D21: Lead Product Insight Analyst | E21: Advanced Professional, Technical Product Management-IND | F21: PT4 - Advanced Professional | G21: 44599 | H21: 3 - 5 Years | I21: 1 year(s), 2 month(s), 18 day(s) | J21: Solid | K21: Strong | L21: High | M21: High | N21: {=IF(OR(L21="",M21=""),"", IF(OR(ISNA(MATCH(L21,{"Low","Medium","High"},0)), ISNA(MATCH(M21,{"Low","Medium","High"},0))),"",_xlfn.SWITCH(L21,"Low",1,"Medium",2,"High",3) + 3 * _xlfn.SWITCH(M21,"Low",1,"Medium",2,"High",3) - 3))} -> 9 | O21: 9.Top Talent | P21: =IFERROR(VLOOKUP(O21,'Excel Table (Do Not Format)'!A:D,2,FALSE),"") -> Top Talent [H,H] | Q21: =IFERROR(VLOOKUP(O21,'Excel Table (Do Not Format)'!A:D,3,FALSE),"") -> identify stretch experiences or temporary assignments, increase executive exposure | R21: =IFERROR(VLOOKUP(O21,'Excel Table (Do Not Format)'!A:D,4,FALSE),"") -> Differentially Invest - Ensure career discussions are happening regualrly? Do they have an individual development plan? What opportunities exist to accelerate development and growth? Revisit talent often to plan for next steps. | U21: Hitesh Bakutra | V21: Elizabeth Benker | W21: Erin Howard | X21: Hitesh Bakutra
A22: 2074 | B22: David Cooperberg | C22: Lead Product Manager | D22: Lead Product Manager | E22: Advanced Professional, Product Management-USA | F22: PT4 - Advanced Professional | G22: 43206 | H22: 5 - 10 Years | I22: 1 year(s), 5 month(s), 10 day(s) | J22: Solid | K22: Solid | L22: High | M22: High | N22: {=IF(OR(L22="",M22=""),"", IF(OR(ISNA(MATCH(L22,{"Low","Medium","High"},0)), ISNA(MATCH(M22,{"Low","Medium","High"},0))),"",_xlfn.SWITCH(L22,"Low",1,"Medium",2,"High",3) + 3 * _xlfn.SWITCH(M22,"Low",1,"Medium",2,"High",3) - 3))} -> 9 | O22: 9.Top Talent | P22: =IFERROR(VLOOKUP(O22,'Excel Table (Do Not Format)'!A:D,2,FALSE),"") -> Top Talent [H,H] | Q22: =IFERROR(VLOOKUP(O22,'Excel Table (Do Not Format)'!A:D,3,FALSE),"") -> identify stretch experiences or temporary assignments, increase executive exposure | R22: =IFERROR(VLOOKUP(O22,'Excel Table (Do Not Format)'!A:D,4,FALSE),"") -> Differentially Invest - Ensure career discussions are happening regualrly? Do they have an individual development plan? What opportunities exist to accelerate development and growth? Revisit talent often to plan for next steps. | T22: Yes | U22: Kate Butcher | V22: Chad Thompson | W22: Kate Butcher
A23: 101003 | B23: David Domagalski | C23: Advanced Professional, Technical Writer-USA | D23: Advanced Professional, Technical Writer-USA | E23: Advanced Professional, Technical Writer-USA | F23: PT4 - Advanced Professional | G23: 43808 | H23: 5 - 10 Years | I23: 1 year(s), 8 month(s), 16 day(s) | J23: Strong | K23: Strong | L23: High | M23: Medium | N23: {=IF(OR(L23="",M23=""),"", IF(OR(ISNA(MATCH(L23,{"Low","Medium","High"},0)), ISNA(MATCH(M23,{"Low","Medium","High"},0))),"",_xlfn.SWITCH(L23,"Low",1,"Medium",2,"High",3) + 3 * _xlfn.SWITCH(M23,"Low",1,"Medium",2,"High",3) - 3))} -> 6 | O23: 5. Core Talent | P23: =IFERROR(VLOOKUP(O23,'Excel Table (Do Not Format)'!A:D,2,FALSE),"") -> Core Talent [M,M] | Q23: =IFERROR(VLOOKUP(O23,'Excel Table (Do Not Format)'!A:D,3,FALSE),"") -> identify performance barriers, explore portential to expand responsibilties in current role and discuss career aspirations (ideally for talent new in role) | R23: =IFERROR(VLOOKUP(O23,'Excel Table (Do Not Format)'!A:D,4,FALSE),"") -> Develop in Role - Identify developmental activities to continue to grow their skill and set them up for success for anticiapted progression | U23: Marcela Abrach | V23: Elizabeth Benker | W23: Marcela Abrach
A24: 1885 | B24: David Skala | C24: Principal, Product Designer | D24: Principal, UI/UX Designer-CZE | E24: Principal, UI/UX Designer-CZE | F24: PT5 - Principal | G24: 42765 | H24: 5 - 10 Years | I24: 0 year(s), 8 month(s), 18 day(s) | J24: Strong | K24: Leading | L24: High | M24: Medium | N24: {=IF(OR(L24="",M24=""),"", IF(OR(ISNA(MATCH(L24,{"Low","Medium","High"},0)), ISNA(MATCH(M24,{"Low","Medium","High"},0))),"",_xlfn.SWITCH(L24,"Low",1,"Medium",2,"High",3) + 3 * _xlfn.SWITCH(M24,"Low",1,"Medium",2,"High",3) - 3))} -> 6 | O24: 8. Growth Talent | P24: =IFERROR(VLOOKUP(O24,'Excel Table (Do Not Format)'!A:D,2,FALSE),"") -> Growth Talent [M,H] | Q24: =IFERROR(VLOOKUP(O24,'Excel Table (Do Not Format)'!A:D,3,FALSE),"") -> identify performance barriers, explore portential to expand responsibilties in current role | R24: =IFERROR(VLOOKUP(O24,'Excel Table (Do Not Format)'!A:D,4,FALSE),"") -> Differentially Invest - Ensure career discussions are happening regualrly? Do they have an individual development plan? What opportunities exist to accelerate development and growth? Revisit talent often to plan for next steps. | S24: David is still getting used to Principal position and looking for the right way to have more impact. | T24: No | U24: Patrik Volek | V24: Elizabeth Benker | W24: Patrik Volek
A25: 105566 | B25: Dhiraj Sahu | C25: Senior Product Analyst | D25: Sr. Professional, Technical Product Management-IND | E25: Sr. Professional, Technical Product Management-IND | F25: PT3 - Sr. Professional | G25: 45537 | H25: 13 - 18 Months | I25: 1 year(s), 2 month(s), 17 day(s) | K25: Solid | L25: Medium | M25: High | N25: {=IF(OR(L25="",M25=""),"", IF(OR(ISNA(MATCH(L25,{"Low","Medium","High"},0)), ISNA(MATCH(M25,{"Low","Medium","High"},0))),"",_xlfn.SWITCH(L25,"Low",1,"Medium",2,"High",3) + 3 * _xlfn.SWITCH(M25,"Low",1,"Medium",2,"High",3) - 3))} -> 8 | O25: 8. Growth Talent | P25: =IFERROR(VLOOKUP(O25,'Excel Table (Do Not Format)'!A:D,2,FALSE),"") -> Growth Talent [M,H] | Q25: =IFERROR(VLOOKUP(O25,'Excel Table (Do Not Format)'!A:D,3,FALSE),"") -> identify performance barriers, explore portential to expand responsibilties in current role | R25: =IFERROR(VLOOKUP(O25,'Excel Table (Do Not Format)'!A:D,4,FALSE),"") -> Differentially Invest - Ensure career discussions are happening regualrly? Do they have an individual development plan? What opportunities exist to accelerate development and growth? Revisit talent often to plan for next steps. | U25: Hitesh Bakutra | V25: Elizabeth Benker | W25: Erin Howard | X25: Hitesh Bakutra
A26: 2011 | B26: Elad Idan | C26: Lead Pricing Manager | D26: Advanced Professional, Technical Program Management-USA | E26: Advanced Professional, Technical Program Management-USA | F26: PT4 - Advanced Professional | G26: 43136 | H26: 5 - 10 Years | I26: 1 year(s), 8 month(s), 16 day(s) | J26: Strong | K26: Solid | L26: High | M26: Low | N26: {=IF(OR(L26="",M26=""),"", IF(OR(ISNA(MATCH(L26,{"Low","Medium","High"},0)), ISNA(MATCH(M26,{"Low","Medium","High"},0))),"",_xlfn.SWITCH(L26,"Low",1,"Medium",2,"High",3) + 3 * _xlfn.SWITCH(M26,"Low",1,"Medium",2,"High",3) - 3))} -> 3 | O26: 3. Expert Talent | P26: =IFERROR(VLOOKUP(O26,'Excel Table (Do Not Format)'!A:D,2,FALSE),"") -> Expert Talent [H,L] | Q26: =IFERROR(VLOOKUP(O26,'Excel Table (Do Not Format)'!A:D,3,FALSE),"") -> leverage experience to mentor and growth others | R26: =IFERROR(VLOOKUP(O26,'Excel Table (Do Not Format)'!A:D,4,FALSE),"") -> Develop in Role - Identify developmental activities to continue to grow their skill and set them up for success for anticiapted progression | S26: Elad and I had a discussion about his career path. He has reached the limits of growth in PE. We aligned that he needs to explore a broader GTM architect role otuside of PE. Over the next 6 mos, I would like him to take ownership of adjacent areas such as what would it take to support In-app purchase in collaboration with the PE team and the broader GTM org etc. He is also going to take courses to train for such a role. | U26: Ani Worlikar | V26: Ani Worlikar
A27: 102702 | B27: Emily Davis (On Leave) | C27: Senior Product Designer | D27: Sr. Professional, UI/UX Designer-AUS | E27: Sr. Professional, UI/UX Designer-AUS | F27: PT3 - Sr. Professional | G27: 44476 | H27: 5 - 10 Years | I27: 4 year(s), 1 month(s), 12 day(s) | J27: Solid | L27: High | M27: High | N27: {=IF(OR(L27="",M27=""),"", IF(OR(ISNA(MATCH(L27,{"Low","Medium","High"},0)), ISNA(MATCH(M27,{"Low","Medium","High"},0))),"",_xlfn.SWITCH(L27,"Low",1,"Medium",2,"High",3) + 3 * _xlfn.SWITCH(M27,"Low",1,"Medium",2,"High",3) - 3))} -> 9 | O27: 9.Top Talent | P27: =IFERROR(VLOOKUP(O27,'Excel Table (Do Not Format)'!A:D,2,FALSE),"") -> Top Talent [H,H] | Q27: =IFERROR(VLOOKUP(O27,'Excel Table (Do Not Format)'!A:D,3,FALSE),"") -> identify stretch experiences or temporary assignments, increase executive exposure | R27: =IFERROR(VLOOKUP(O27,'Excel Table (Do Not Format)'!A:D,4,FALSE),"") -> Differentially Invest - Ensure career discussions are happening regualrly? Do they have an individual development plan? What opportunities exist to accelerate development and growth? Revisit talent often to plan for next steps. | U27: Will Hurley | V27: Elizabeth Benker | W27: Will Hurley
A28: 102844 | B28: Emily Turner | C28: Advanced Professional, UI/UX Designer-USA | D28: Advanced Professional, UI/UX Designer-USA | E28: Advanced Professional, UI/UX Designer-USA | F28: PT4 - Advanced Professional | G28: 44508 | H28: 3 - 5 Years | I28: 1 year(s), 8 month(s), 16 day(s) | J28: Leading | K28: Strong | L28: High | M28: Medium | N28: {=IF(OR(L28="",M28=""),"", IF(OR(ISNA(MATCH(L28,{"Low","Medium","High"},0)), ISNA(MATCH(M28,{"Low","Medium","High"},0))),"",_xlfn.SWITCH(L28,"Low",1,"Medium",2,"High",3) + 3 * _xlfn.SWITCH(M28,"Low",1,"Medium",2,"High",3) - 3))} -> 6 | O28: 6.High Impact Talent | P28: =IFERROR(VLOOKUP(O28,'Excel Table (Do Not Format)'!A:D,2,FALSE),"") -> High Impact Talent [H,M] | Q28: =IFERROR(VLOOKUP(O28,'Excel Table (Do Not Format)'!A:D,3,FALSE),"") -> expand responsibilities in current role, identify key experiences and increase executive exposure | R28: =IFERROR(VLOOKUP(O28,'Excel Table (Do Not Format)'!A:D,4,FALSE),"") -> Differentially Invest - Ensure career discussions are happening regualrly? Do they have an individual development plan? What opportunities exist to accelerate development and growth? Revisit talent often to plan for next steps. | T28: No | U28: Elizabeth Benker | V28: Elizabeth Benker
A29: 106330 | B29: Gabe Keaveney | C29: Pricing Strategy Analyst | D29: Professional, Competitive Intelligence-USA | E29: Professional, Competitive Intelligence-USA | F29: PT2 - Professional | G29: 45922 | H29: 0 - 3 Months | I29: 0 year(s), 1 month(s), 28 day(s) | O29: 5. Core Talent | P29: =IFERROR(VLOOKUP(O29,'Excel Table (Do Not Format)'!A:D,2,FALSE),"") -> Core Talent [M,M] | Q29: =IFERROR(VLOOKUP(O29,'Excel Table (Do Not Format)'!A:D,3,FALSE),"") -> identify performance barriers, explore portential to expand responsibilties in current role and discuss career aspirations (ideally for talent new in role) | R29: =IFERROR(VLOOKUP(O29,'Excel Table (Do Not Format)'!A:D,4,FALSE),"") -> Develop in Role - Identify developmental activities to continue to grow their skill and set them up for success for anticiapted progression | S29: Recent hire. Shows good potential. Continue to develop over the next 6 mos | T29: No | U29: Ani Worlikar | V29: Ani Worlikar
A30: 100735 | B30: Gayatri Kakarlapudi | C30: Product Manager | D30: Professional, Product Management-USA | E30: Professional, Product Management-USA | F30: PT2 - Professional | G30: 43689 | H30: 5 - 10 Years | I30: 3 year(s), 5 month(s), 18 day(s) | J30: Solid | K30: Solid | L30: Medium | M30: Medium | N30: {=IF(OR(L30="",M30=""),"", IF(OR(ISNA(MATCH(L30,{"Low","Medium","High"},0)), ISNA(MATCH(M30,{"Low","Medium","High"},0))),"",_xlfn.SWITCH(L30,"Low",1,"Medium",2,"High",3) + 3 * _xlfn.SWITCH(M30,"Low",1,"Medium",2,"High",3) - 3))} -> 5 | O30: 5. Core Talent | P30: =IFERROR(VLOOKUP(O30,'Excel Table (Do Not Format)'!A:D,2,FALSE),"") -> Core Talent [M,M] | Q30: =IFERROR(VLOOKUP(O30,'Excel Table (Do Not Format)'!A:D,3,FALSE),"") -> identify performance barriers, explore portential to expand responsibilties in current role and discuss career aspirations (ideally for talent new in role) | R30: =IFERROR(VLOOKUP(O30,'Excel Table (Do Not Format)'!A:D,4,FALSE),"") -> Develop in Role - Identify developmental activities to continue to grow their skill and set them up for success for anticiapted progression | T30: No | U30: Rachel Howard | V30: Laura Williams Argilla | W30: Rachel Howard
A31: 102824 | B31: Geoffrey Zath | C31: Sr. Professional, Technical Writer-USA | D31: Sr. Professional, Technical Writer-USA | E31: Sr. Professional, Technical Writer-USA | F31: PT3 - Sr. Professional | G31: 44508 | H31: 3 - 5 Years | I31: 0 year(s), 8 month(s), 17 day(s) | J31: Strong | K31: Leading | L31: Medium | M31: Medium | N31: {=IF(OR(L31="",M31=""),"", IF(OR(ISNA(MATCH(L31,{"Low","Medium","High"},0)), ISNA(MATCH(M31,{"Low","Medium","High"},0))),"",_xlfn.SWITCH(L31,"Low",1,"Medium",2,"High",3) + 3 * _xlfn.SWITCH(M31,"Low",1,"Medium",2,"High",3) - 3))} -> 5 | O31: 5. Core Talent | P31: =IFERROR(VLOOKUP(O31,'Excel Table (Do Not Format)'!A:D,2,FALSE),"") -> Core Talent [M,M] | Q31: =IFERROR(VLOOKUP(O31,'Excel Table (Do Not Format)'!A:D,3,FALSE),"") -> identify performance barriers, explore portential to expand responsibilties in current role and discuss career aspirations (ideally for talent new in role) | R31: =IFERROR(VLOOKUP(O31,'Excel Table (Do Not Format)'!A:D,4,FALSE),"") -> Develop in Role - Identify developmental activities to continue to grow their skill and set them up for success for anticiapted progression | U31: Marcela Abrach | V31: Elizabeth Benker | W31: Marcela Abrach
A32: 106012 | B32: Gita Ligure | C32: UI/UX Researcher | D32: Professional, UI/UX Researcher-USA | E32: Professional, UI/UX Researcher-USA | F32: PT2 - Professional | G32: 45706 | H32: 7 - 9 Months | I32: 0 year(s), 9 month(s), 1 day(s) | L32: Medium | M32: Medium | N32: {=IF(OR(L32="",M32=""),"", IF(OR(ISNA(MATCH(L32,{"Low","Medium","High"},0)), ISNA(MATCH(M32,{"Low","Medium","High"},0))),"",_xlfn.SWITCH(L32,"Low",1,"Medium",2,"High",3) + 3 * _xlfn.SWITCH(M32,"Low",1,"Medium",2,"High",3) - 3))} -> 5 | O32: 8. Growth Talent | P32: =IFERROR(VLOOKUP(O32,'Excel Table (Do Not Format)'!A:D,2,FALSE),"") -> Growth Talent [M,H] | Q32: =IFERROR(VLOOKUP(O32,'Excel Table (Do Not Format)'!A:D,3,FALSE),"") -> identify performance barriers, explore portential to expand responsibilties in current role | R32: =IFERROR(VLOOKUP(O32,'Excel Table (Do Not Format)'!A:D,4,FALSE),"") -> Differentially Invest - Ensure career discussions are happening regualrly? Do they have an individual development plan? What opportunities exist to accelerate development and growth? Revisit talent often to plan for next steps. | T32: No | U32: Olga Ziegelman | V32: Elizabeth Benker | W32: Erin Howard | X32: Olga Ziegelman
A33: 101443 | B33: Greg Filla (On Leave) | C33: Lead Product Manager | D33: Advanced Professional, Product Management-USA | E33: Advanced Professional, Product Management-USA | F33: PT4 - Advanced Professional | G33: 44067 | H33: 5 - 10 Years | I33: 1 year(s), 5 month(s), 18 day(s) | J33: Solid | K33: Strong | L33: Medium | M33: Medium | N33: {=IF(OR(L33="",M33=""),"", IF(OR(ISNA(MATCH(L33,{"Low","Medium","High"},0)), ISNA(MATCH(M33,{"Low","Medium","High"},0))),"",_xlfn.SWITCH(L33,"Low",1,"Medium",2,"High",3) + 3 * _xlfn.SWITCH(M33,"Low",1,"Medium",2,"High",3) - 3))} -> 5 | O33: 5. Core Talent | P33: =IFERROR(VLOOKUP(O33,'Excel Table (Do Not Format)'!A:D,2,FALSE),"") -> Core Talent [M,M] | Q33: =IFERROR(VLOOKUP(O33,'Excel Table (Do Not Format)'!A:D,3,FALSE),"") -> identify performance barriers, explore portential to expand responsibilties in current role and discuss career aspirations (ideally for talent new in role) | R33: =IFERROR(VLOOKUP(O33,'Excel Table (Do Not Format)'!A:D,4,FALSE),"") -> Develop in Role - Identify developmental activities to continue to grow their skill and set them up for success for anticiapted progression | T33: No | U33: Nicole Johnson | V33: Laura Williams Argilla | W33: Nicole Johnson
A34: 105985 | B34: Harsh Jiladiya | C34: Product Analyst | D34: Professional, Technical Product Management-IND | E34: Professional, Technical Product Management-IND | F34: PT2 - Professional | G34: 45707 | H34: 7 - 9 Months | I34: 0 year(s), 9 month(s), 0 day(s) | L34: High | M34: High | N34: {=IF(OR(L34="",M34=""),"", IF(OR(ISNA(MATCH(L34,{"Low","Medium","High"},0)), ISNA(MATCH(M34,{"Low","Medium","High"},0))),"",_xlfn.SWITCH(L34,"Low",1,"Medium",2,"High",3) + 3 * _xlfn.SWITCH(M34,"Low",1,"Medium",2,"High",3) - 3))} -> 9 | O34: 9.Top Talent | P34: =IFERROR(VLOOKUP(O34,'Excel Table (Do Not Format)'!A:D,2,FALSE),"") -> Top Talent [H,H] | Q34: =IFERROR(VLOOKUP(O34,'Excel Table (Do Not Format)'!A:D,3,FALSE),"") -> identify stretch experiences or temporary assignments, increase executive exposure | R34: =IFERROR(VLOOKUP(O34,'Excel Table (Do Not Format)'!A:D,4,FALSE),"") -> Differentially Invest - Ensure career discussions are happening regualrly? Do they have an individual development plan? What opportunities exist to accelerate development and growth? Revisit talent often to plan for next steps. | U34: Hitesh Bakutra | V34: Elizabeth Benker | W34: Erin Howard | X34: Hitesh Bakutra
A35: 105835 | B35: HEMANTI PRADHAN | C35: Technical Writer | D35: Professional, Technical Writer-IND | E35: Professional, Technical Writer-IND | F35: PT2 - Professional | G35: 45677 | H35: 7 - 9 Months | I35: 0 year(s), 9 month(s), 30 day(s) | L35: Medium | M35: Medium | N35: {=IF(OR(L35="",M35=""),"", IF(OR(ISNA(MATCH(L35,{"Low","Medium","High"},0)), ISNA(MATCH(M35,{"Low","Medium","High"},0))),"",_xlfn.SWITCH(L35,"Low",1,"Medium",2,"High",3) + 3 * _xlfn.SWITCH(M35,"Low",1,"Medium",2,"High",3) - 3))} -> 5 | O35: 5. Core Talent | P35: =IFERROR(VLOOKUP(O35,'Excel Table (Do Not Format)'!A:D,2,FALSE),"") -> Core Talent [M,M] | Q35: =IFERROR(VLOOKUP(O35,'Excel Table (Do Not Format)'!A:D,3,FALSE),"") -> identify performance barriers, explore portential to expand responsibilties in current role and discuss career aspirations (ideally for talent new in role) | R35: =IFERROR(VLOOKUP(O35,'Excel Table (Do Not Format)'!A:D,4,FALSE),"") -> Develop in Role - Identify developmental activities to continue to grow their skill and set them up for success for anticiapted progression | U35: Marcela Abrach | V35: Elizabeth Benker | W35: Marcela Abrach
A36: 100583 | B36: Iryna Onishchuk (Ірина Оніщук) | C36: Sr. Product Delivery Program Manager | D36: Sr. Professional, Technical Program Management-CZE | E36: Sr. Professional, Technical Program Management-CZE | F36: PT3 - Sr. Professional | G36: 43598 | H36: 5 - 10 Years | I36: 1 year(s), 8 month(s), 18 day(s) | J36: Solid | K36: Strong | L36: High | M36: High | N36: {=IF(OR(L36="",M36=""),"", IF(OR(ISNA(MATCH(L36,{"Low","Medium","High"},0)), ISNA(MATCH(M36,{"Low","Medium","High"},0))),"",_xlfn.SWITCH(L36,"Low",1,"Medium",2,"High",3) + 3 * _xlfn.SWITCH(M36,"Low",1,"Medium",2,"High",3) - 3))} -> 9 | O36: 9.Top Talent | P36: =IFERROR(VLOOKUP(O36,'Excel Table (Do Not Format)'!A:D,2,FALSE),"") -> Top Talent [H,H] | Q36: =IFERROR(VLOOKUP(O36,'Excel Table (Do Not Format)'!A:D,3,FALSE),"") -> identify stretch experiences or temporary assignments, increase executive exposure | R36: =IFERROR(VLOOKUP(O36,'Excel Table (Do Not Format)'!A:D,4,FALSE),"") -> Differentially Invest - Ensure career discussions are happening regualrly? Do they have an individual development plan? What opportunities exist to accelerate development and growth? Revisit talent often to plan for next steps. | S36: Has much potential with move to new CSIG team to advance with new responsbilities. | T36: No | U36: Carolyn Blanco Losada | V36: Elizabeth Benker | W36: Erin Howard | X36: Carolyn Blanco Losada
A37: 105280 | B37: Ishita Gandhi | C37: UX Copywriter | D37: Professional, UI/UX Designer-IND | E37: Professional, UI/UX Designer-IND | F37: PT2 - Professional | G37: 45343 | H37: 19 - 24 Months | I37: 1 year(s), 8 month(s), 29 day(s) | K37: Solid | L37: High | M37: Medium | N37: {=IF(OR(L37="",M37=""),"", IF(OR(ISNA(MATCH(L37,{"Low","Medium","High"},0)), ISNA(MATCH(M37,{"Low","Medium","High"},0))),"",_xlfn.SWITCH(L37,"Low",1,"Medium",2,"High",3) + 3 * _xlfn.SWITCH(M37,"Low",1,"Medium",2,"High",3) - 3))} -> 6 | O37: 6.High Impact Talent | P37: =IFERROR(VLOOKUP(O37,'Excel Table (Do Not Format)'!A:D,2,FALSE),"") -> High Impact Talent [H,M] | Q37: =IFERROR(VLOOKUP(O37,'Excel Table (Do Not Format)'!A:D,3,FALSE),"") -> expand responsibilities in current role, identify key experiences and increase executive exposure | R37: =IFERROR(VLOOKUP(O37,'Excel Table (Do Not Format)'!A:D,4,FALSE),"") -> Differentially Invest - Ensure career discussions are happening regualrly? Do they have an individual development plan? What opportunities exist to accelerate development and growth? Revisit talent often to plan for next steps. | T37: Yes | U37: Elizabeth Benker | V37: Elizabeth Benker
A38: 104041 | B38: Jarrod Thuener | C38: Sr. Product Manager | D38: Sr. Professional, Product Management-USA | E38: Sr. Professional, Product Management-USA | F38: PT3 - Sr. Professional | G38: 44733 | H38: 3 - 5 Years | I38: 2 year(s), 10 month(s), 16 day(s) | J38: Solid | K38: Strong | L38: Medium | M38: Medium | N38: {=IF(OR(L38="",M38=""),"", IF(OR(ISNA(MATCH(L38,{"Low","Medium","High"},0)), ISNA(MATCH(M38,{"Low","Medium","High"},0))),"",_xlfn.SWITCH(L38,"Low",1,"Medium",2,"High",3) + 3 * _xlfn.SWITCH(M38,"Low",1,"Medium",2,"High",3) - 3))} -> 5 | O38: 5. Core Talent | P38: =IFERROR(VLOOKUP(O38,'Excel Table (Do Not Format)'!A:D,2,FALSE),"") -> Core Talent [M,M] | Q38: =IFERROR(VLOOKUP(O38,'Excel Table (Do Not Format)'!A:D,3,FALSE),"") -> identify performance barriers, explore portential to expand responsibilties in current role and discuss career aspirations (ideally for talent new in role) | R38: =IFERROR(VLOOKUP(O38,'Excel Table (Do Not Format)'!A:D,4,FALSE),"") -> Develop in Role - Identify developmental activities to continue to grow their skill and set them up for success for anticiapted progression | T38: No | U38: Kate Butcher | V38: Chad Thompson | W38: Kate Butcher
A39: 102723 | B39: JASON GAYLORD | C39: UX Researcher | D39: Professional, UI/UX Researcher-USA | E39: Professional, UI/UX Researcher-USA | F39: PT2 - Professional | G39: 44487 | H39: 3 - 5 Years | I39: 4 year(s), 1 month(s), 1 day(s) | J39: Solid | K39: Strong | L39: High | M39: Medium | N39: {=IF(OR(L39="",M39=""),"", IF(OR(ISNA(MATCH(L39,{"Low","Medium","High"},0)), ISNA(MATCH(M39,{"Low","Medium","High"},0))),"",_xlfn.SWITCH(L39,"Low",1,"Medium",2,"High",3) + 3 * _xlfn.SWITCH(M39,"Low",1,"Medium",2,"High",3) - 3))} -> 6 | O39: 9.Top Talent | P39: =IFERROR(VLOOKUP(O39,'Excel Table (Do Not Format)'!A:D,2,FALSE),"") -> Top Talent [H,H] | Q39: =IFERROR(VLOOKUP(O39,'Excel Table (Do Not Format)'!A:D,3,FALSE),"") -> identify stretch experiences or temporary assignments, increase executive exposure | R39: =IFERROR(VLOOKUP(O39,'Excel Table (Do Not Format)'!A:D,4,FALSE),"") -> Differentially Invest - Ensure career discussions are happening regualrly? Do they have an individual development plan? What opportunities exist to accelerate development and growth? Revisit talent often to plan for next steps. | S39: Has been operating at a senior level - supporting the Canvas pillar. Great soft skills, fantatsic team player, strong research skills. Strong positive feedback from other UXR, Design and PM on his work. | T39: Yes | U39: Olga Ziegelman | V39: Elizabeth Benker | W39: Erin Howard
A40: 106369 | B40: Jay Shipley | C40: Sr. Principal Product Manager | D40: Sr. Principal, Product Management-USA | E40: Sr. Principal, Product Management-USA | F40: PT6 - Sr. Principal | G40: 45943 | H40: 0 - 3 Months | I40: 0 year(s), 1 month(s), 6 day(s) | O40: 5. Core Talent | P40: =IFERROR(VLOOKUP(O40,'Excel Table (Do Not Format)'!A:D,2,FALSE),"") -> Core Talent [M,M] | Q40: =IFERROR(VLOOKUP(O40,'Excel Table (Do Not Format)'!A:D,3,FALSE),"") -> identify performance barriers, explore portential to expand responsibilties in current role and discuss career aspirations (ideally for talent new in role) | R40: =IFERROR(VLOOKUP(O40,'Excel Table (Do Not Format)'!A:D,4,FALSE),"") -> Develop in Role - Identify developmental activities to continue to grow their skill and set them up for success for anticiapted progression | U40: Chad Thompson | V40: Chad Thompson
...

Sheet Excel Table (Do Not Format)
A1: EOY25 Talent Indicator | B1: Talent Mapping Position | C1: Development Focus | D1: Development Action
A2: 7. Emerging Talent/ Off-Track | B2: Emerging Talent/ Off-Track [L,H] | C2: drive performance in current role and re-evaluate in 6-12 months | D2: Evaluate Fit - What is causing them to underperform? Are they in the right role? Do they need a mentor and/or additional guidance?
A3: 4. Inconsistent Talent | B3: Inconsistent Talent [L,M] | C3: re-establish performance expectations in current role, drive performance and re-evaluate in 6-12 months | D3: Evaluate Fit/Make A Plan - Identify a coaching plan to improve performance
A4: 1. Underperforming Talent | B4: Underperforming Talent [L,L] | C4: re-assign or manage out of Alteryx | D4: Make A Plan - Identify a plan to improve performance in partnership with HR
A5: 8. Growth Talent | B5: Growth Talent [M,H] | C5: identify performance barriers, explore portential to expand responsibilties in current role | D5: Differentially Invest - Ensure career discussions are happening regualrly? Do they have an individual development plan? What opportunities exist to accelerate development and growth? Revisit talent often to plan for next steps.
A6: 5. Core Talent | B6: Core Talent [M,M] | C6: identify performance barriers, explore portential to expand responsibilties in current role and discuss career aspirations (ideally for talent new in role) | D6: Develop in Role - Identify developmental activities to continue to grow their skill and set them up for success for anticiapted progression
A7: 2. Solid Talent | B7: Solid Talent [M,L] | C7: consider expanding current role, explore lateral/development opportunities | D7: Develop in Role - Identify developmental activities to continue to grow their skill and set them up for success for anticiapted progression
A8: 9.Top Talent | B8: Top Talent [H,H] | C8: identify stretch experiences or temporary assignments, increase executive exposure | D8: Differentially Invest - Ensure career discussions are happening regualrly? Do they have an individual development plan? What opportunities exist to accelerate development and growth? Revisit talent often to plan for next steps.
A9: 6.High Impact Talent | B9: High Impact Talent [H,M] | C9: expand responsibilities in current role, identify key experiences and increase executive exposure | D9: Differentially Invest - Ensure career discussions are happening regualrly? Do they have an individual development plan? What opportunities exist to accelerate development and growth? Revisit talent often to plan for next steps.
A10: 3. Expert Talent | B10: Expert Talent [H,L] | C10: leverage experience to mentor and growth others | D10: Develop in Role - Identify developmental activities to continue to grow their skill and set them up for success for anticiapted progression

Sheet Pivot
A3: 9- Box Calibration | B3: Count of Worker | D3: Count of Worker
A4: Core Talent [M,M] | B4: 45 | D4: Talent Mapping Position [Performance vs Potential] | E4: Worker | F4: Total
A5: Expert Talent [H,L] | B5: 2 | D5: Core Talent [M,M] | E5: Adriana Rybarova | F5: 1
A6: Growth Talent [M,H] | B6: 10 | E6: Alexandra Zelinskaya | F6: 1
A7: High Impact Talent [H,M] | B7: 7 | E7: Alicia Beam | F7: 1
A8: Solid Talent [M,L] | B8: 3 | E8: Apurva Mathur | F8: 1
A9: Top Talent [H,H] | B9: 15 | E9: ARPIT VERMA | F9: 1
A10: Underperforming Talent [L,L] | B10: 3 | E10: Ashutosh Kumar | F10: 1
A11: (blank) | E11: Baneen Bryan | F11: 1
A12: Inconsistent Talent [L,M] | B12: 5 | E12: Bob Fraser | F12: 1
B13: 2 | E13: David Domagalski | F13: 1
A14: Grand Total | B14: 92 | E14: Gabe Keaveney | F14: 1
E15: Gayatri Kakarlapudi | F15: 1
E16: Geoffrey Zath | F16: 1
E17: Greg Filla (On Leave) | F17: 1
E18: HEMANTI PRADHAN | F18: 1
E19: Jarrod Thuener | F19: 1
E20: Jay Shipley | F20: 1
E21: Jiří Peroutka | F21: 1
E22: Joanna Hoge | F22: 1
E23: Kateřina Rutová | F23: 1
E24: Kira Droganova | F24: 1
E25: Liana Ahn | F25: 1
E26: Lucy Durand | F26: 1
... E49: Ximena Arce | F49: 1
D50: Core Talent [M,M] Total | F50: 45
D51: Expert Talent [H,L] | E51: Elad Idan | F51: 1
E52: Trevor Harris | F52: 1
D53: Expert Talent [H,L] Total | F53: 2
D54: Growth Talent [M,H] | E54: Agnimitra Pathak | F54: 1
E55: David Skala | F55: 1
E56: Dhiraj Sahu | F56: 1
E57: Gita Ligure | F57: 1
E58: Jinju Hopkins (On Leave) | F58: 1
E59: Kyle Hamm | F59: 1
E60: Peter Ott | F60: 1
E61: Pranjal Uday | F61: 1
E62: Raffaela Bethke | F62: 1
E63: Rithi Son | F63: 1
D64: Growth Talent [M,H] Total | F64: 10
...
