Workbook
Name Yes: 'PUX Mgrs '!#REF!

Sheet Definitions & Instructions
A1: Instructions:
A2: Note the most current trending rating from Aug 25, for your Employee in column L ,M, N (PLEASE DO NOT CHANGE) . Column O is pre-seeded with Aug 25 Talent Assessment Mappings and will be discussed during PUX Calibration Tues.Dec 2 , please modify based upon a combination of observations and feedback received .
A3: The columns M, N and O will auto-populate to help you decide if the performance vs the potential has been accurately plotted per the definitions.
A4: Add notes on where you need support from the discussion or if you want to call out any feedback in advance of the discussion. For example: if someone new in role has been rated Strong or Needs Focus or will be presented for a promotion
A7: Performance: Consistency and level of impact in current and past roles (Low / Medium / High).
A8: Potential: Likelihood of success in more complex or senior roles (Low / Medium / High).
A11: FY25 Talent Indicator | B11: Talent Mapping Position [Performance vs Potential] | C11: Development Focus | D11: Development Action
A12: 1. Underperforming Talent | B12: Underperforming Talent [L,L] | C12: re-assign or manage out of Alteryx | D12: Make A Plan - Identify a plan to improve performance in partnership with HR
A13: 2. Solid Talent | B13: Solid Talent [M,L] | C13: consider expanding current role, explore lateral/development opportunities | D13: Develop in Role - Identify developmental activities to continue to grow their skill and set them up for success for anticipated progression
A14: 3. Expert Talent | B14: Expert Talent [H,L] | C14: leverage experience to mentor and growth others | D14: Develop in Role - Identify developmental activities to continue to grow their skill and set them up for success for anticipated progression
A15: 4. Inconsistent Talent | B15: Inconsistent Talent [L,M] | C15: re-establish performance expectations in current role, drive performance and re-evaluate in 6-12 months | D15: Evaluate Fit/Make A Plan - Identify a coaching plan to improve performance
A16: 5. Core Talent | B16: Core Talent [M,M] | C16: identify performance barriers, explore potential to expand responsibilities in current role and discuss career aspirations (ideally for talent new in role) | D16: Develop in Role - Identify developmental activities to continue to grow their skill and set them up for success for anticipated progression
A17: 6.High Impact Talent | B17: High Impact Talent [H,M] | C17: expand responsibilities in current role, identify key experiences and increase executive exposure | D17: Differentially Invest - Ensure career discussions are happening regularly? Do they have an individual development plan? What opportunities exist to accelerate development and growth? Revist talent often to plan for next steps.
A18: 7. Emerging Talent/ Off-Track | B18: Emerging Talent /Off-track [L,H] | C18: drive performance in current role and re-evaluate in 6-12 months | D18: Evaluate Fit - What is causing them to underperform? Are they in the right role? Do they need a mentor and/or additional guidance?
A19: 8. Growth Talent | B19: Growth Talent [M,H] | C19: identify performance barriers, explore potential to expand responsibilities in current role | D19: Differentially Invest - Ensure career discussions are happening regularly? Do they have an individual development plan? What opportunities exist to accelerate development and growth? Revist talent often to plan for next steps.
A20: 9.Top Talent | B20: Top Talent [H,H] | C20: identify stretch experiences or temporary assignments, increase executive exposure | D20: Differentially Invest - Ensure career discussions are happening regularly? Do they have an individual development plan? What opportunities exist to accelerate development and growth? Revist talent often to plan for next steps.

Sheet PUX Mgrs 
A1: Employee ID | B1: Worker | C1: Business Title | D1: Job Title | E1: Job Profile | F1: Job Level - Primary Position | G1: Hire Date | H1: Tenure Category (Months) | I1: Time in Job Profile | J1: 2023 Completed Performance Rating | K1: 2024 Completed Performance Rating | L1: Aug 2025 Talent Assessment Performance | M1: Aug 2025 Talent Assessment Potential | N1: Aug 2025 Talent Assessment 9-Box Label | O1: FY25 Talent Indicator | P1: Talent Mapping Position [Performance vs Potential] | Q1: Development Focus | R1: Development Action | S1: Notes | T1: Promotion (In-Line, | U1: Worker's Manager | V1: Management Chain - Level 04 | W1: Management Chain - Level 05 | X1: Management Chain - Level 06
A2: 102671 | B2: Carolyn Blanco Losada | C2: Manager, Product Delivery Program Management | D2: Mgr, Technical Program Management-USA | E2: Mgr, Technical Program Management-USA | F2: MT2 - Manager | G2: 44494 | H2: 3 - 5 Years | I2: 2 year(s), 10 month(s), 3 day(s) | J2: Strong | K2: Strong | L2: Low | M2: Medium | N2: {=IF(OR(L2="",M2=""),"", IF(OR(ISNA(MATCH(L2,{"Low","Medium","High"},0)), ISNA(MATCH(M2,{"Low","Medium","High"},0))),"",_xlfn.SWITCH(L2,"Low",1,"Medium",2,"High",3) + 3 * _xlfn.SWITCH(M2,"Low",1,"Medium",2,"High",3) - 3))} -> 4 | O2: 4. Inconsistent Talent | P2: =IFERROR(VLOOKUP(O2,'Excel Table (Do Not Format)'!A:D,2,FALSE),"") -> Inconsistent Talent [L,M] | Q2: =IFERROR(VLOOKUP(O2,'Excel Table (Do Not Format)'!A:D,3,FALSE),"") -> re-establish performance expectations in current role, drive performance and re-evaluate in 6-12 months | R2: =IFERROR(VLOOKUP(O2,'Excel Table (Do Not Format)'!A:D,4,FALSE),"") -> Evaluate Fit/Make A Plan - Identify a coaching plan to improve performance | S2: August rating still holds with inconsistent talent. CBL has gaps in communication, storytelling and executive presence. Her new boss, Erin, is aware of these gaps and together, we're working on a coaching plan. | T2: No | U2: Erin Howard | V2: Elizabeth Benker | W2: Erin Howard
A3: 102674 | B3: Elizabeth Cardinal | C3: Team Lead, UI/UX Design-USA | D3: Team Lead, UI/UX Design-USA | E3: Team Lead, UI/UX Design-USA | F3: MT1 - Team Lead | G3: 44481 | H3: 3 - 5 Years | I3: 1 year(s), 1 month(s), 21 day(s) | J3: Strong | K3: Strong | L3: Medium | M3: Medium | N3: {=IF(OR(L3="",M3=""),"", IF(OR(ISNA(MATCH(L3,{"Low","Medium","High"},0)), ISNA(MATCH(M3,{"Low","Medium","High"},0))),"",_xlfn.SWITCH(L3,"Low",1,"Medium",2,"High",3) + 3 * _xlfn.SWITCH(M3,"Low",1,"Medium",2,"High",3) - 3))} -> 5 | O3: 6.High Impact Talent | P3: =IFERROR(VLOOKUP(O3,'Excel Table (Do Not Format)'!A:D,2,FALSE),"") -> High Impact Talent [H,M] | Q3: =IFERROR(VLOOKUP(O3,'Excel Table (Do Not Format)'!A:D,3,FALSE),"") -> expand responsibilities in current role, identify key experiences and increase executive exposure | R3: =IFERROR(VLOOKUP(O3,'Excel Table (Do Not Format)'!A:D,4,FALSE),"") -> Differentially Invest - Ensure career discussions are happening regularly? Do they have an individual development plan? What opportunities exist to accelerate development and growth? Revisit talent often to plan for next steps. | S3: Elizabeth's performance and potential are improving as she expands her impact in an organization willing to invest in UI improvements. Her current scope and performance put her above a Team Lead role; am seeking promotion to Manager this cycle, along with role expansion. | T3: Yes | U3: Elizabeth Benker | V3: Elizabeth Benker
A4: 106408 | B4: Erin Howard | C4: Sr. Director, Customer Signals | D4: Sr. Dir, UI/UX Research-USA | E4: Sr. Dir, UI/UX Research-USA | F4: MT6 - Sr. Director | G4: 45971 | H4: 0 - 3 Months | I4: 0 year(s), 0 month(s), 9 day(s) | O4: 5. Core Talent | P4: =IFERROR(VLOOKUP(O4,'Excel Table (Do Not Format)'!A:D,2,FALSE),"") -> Core Talent [M,M] | Q4: =IFERROR(VLOOKUP(O4,'Excel Table (Do Not Format)'!A:D,3,FALSE),"") -> identify performance barriers, explore portential to expand responsibilties in current role and discuss career aspirations (ideally for talent new in role) | R4: =IFERROR(VLOOKUP(O4,'Excel Table (Do Not Format)'!A:D,4,FALSE),"") -> Develop in Role - Identify developmental activities to continue to grow their skill and set them up for success for anticiapted progression | S4: Erin has been with the organization a short while and shows great potential. It's too early to assess her performance, however, so I will leave her at a 5 for now. | T4: No | U4: Elizabeth Benker | V4: Elizabeth Benker
A5: 106368 | B5: Francois Planet | C5: Director, Product Management | D5: Dir, Product Management-CZE | E5: Dir, Product Management-CZE | F5: MT5 - Director | G5: 45964 | H5: 0 - 3 Months | I5: 0 year(s), 0 month(s), 16 day(s) | O5: 5. Core Talent | P5: =IFERROR(VLOOKUP(O5,'Excel Table (Do Not Format)'!A:D,2,FALSE),"") -> Core Talent [M,M] | Q5: =IFERROR(VLOOKUP(O5,'Excel Table (Do Not Format)'!A:D,3,FALSE),"") -> identify performance barriers, explore portential to expand responsibilties in current role and discuss career aspirations (ideally for talent new in role) | R5: =IFERROR(VLOOKUP(O5,'Excel Table (Do Not Format)'!A:D,4,FALSE),"") -> Develop in Role - Identify developmental activities to continue to grow their skill and set them up for success for anticiapted progression | U5: Laura Williams Argilla | V5: Laura Williams Argilla
A6: 103216 | B6: Hitesh Bakutra | C6: Group Mgr, Product Management-IND | D6: Group Mgr, Product Management-IND | E6: Group Mgr, Product Management-IND | F6: MT4 - Group Manager | G6: 44599 | H6: 3 - 5 Years | I6: 0 year(s), 8 month(s), 18 day(s) | J6: Strong | K6: Strong | L6: Low | M6: Medium | N6: {=IF(OR(L6="",M6=""),"", IF(OR(ISNA(MATCH(L6,{"Low","Medium","High"},0)), ISNA(MATCH(M6,{"Low","Medium","High"},0))),"",_xlfn.SWITCH(L6,"Low",1,"Medium",2,"High",3) + 3 * _xlfn.SWITCH(M6,"Low",1,"Medium",2,"High",3) - 3))} -> 4 | O6: 5. Core Talent | P6: =IFERROR(VLOOKUP(O6,'Excel Table (Do Not Format)'!A:D,2,FALSE),"") -> Core Talent [M,M] | Q6: =IFERROR(VLOOKUP(O6,'Excel Table (Do Not Format)'!A:D,3,FALSE),"") -> identify performance barriers, explore portential to expand responsibilties in current role and discuss career aspirations (ideally for talent new in role) | R6: =IFERROR(VLOOKUP(O6,'Excel Table (Do Not Format)'!A:D,4,FALSE),"") -> Develop in Role - Identify developmental activities to continue to grow their skill and set them up for success for anticiapted progression | S6: Hitesh blossomed in the last several months under new leadership. He's been responsive, proactive, and focused on the three goals we set out for him. He's also proposing and pursuing significant new improvements in the Telemetry space. | T6: No | U6: Erin Howard | V6: Elizabeth Benker | W6: Erin Howard
A7: 102818 | B7: Kate Butcher | C7: Director, Product Management | D7: Dir, Product Management-USA | E7: Dir, Product Management-USA | F7: MT5 - Director | G7: 44508 | H7: 3 - 5 Years | I7: 1 year(s), 4 month(s), 12 day(s) | J7: Strong | K7: Strong | L7: High | M7: Medium | N7: {=IF(OR(L7="",M7=""),"", IF(OR(ISNA(MATCH(L7,{"Low","Medium","High"},0)), ISNA(MATCH(M7,{"Low","Medium","High"},0))),"",_xlfn.SWITCH(L7,"Low",1,"Medium",2,"High",3) + 3 * _xlfn.SWITCH(M7,"Low",1,"Medium",2,"High",3) - 3))} -> 6 | O7: 6.High Impact Talent | P7: =IFERROR(VLOOKUP(O7,'Excel Table (Do Not Format)'!A:D,2,FALSE),"") -> High Impact Talent [H,M] | Q7: =IFERROR(VLOOKUP(O7,'Excel Table (Do Not Format)'!A:D,3,FALSE),"") -> expand responsibilities in current role, identify key experiences and increase executive exposure | R7: =IFERROR(VLOOKUP(O7,'Excel Table (Do Not Format)'!A:D,4,FALSE),"") -> Differentially Invest - Ensure career discussions are happening regularly? Do they have an individual development plan? What opportunities exist to accelerate development and growth? Revisit talent often to plan for next steps. | U7: Chad Thompson | V7: Chad Thompson
A8: 102384 | B8: Katie Fiscus | C8: Mgr, UI/UX Design-USA | D8: Mgr, UI/UX Design-USA | E8: Mgr, UI/UX Design-USA | F8: MT2 - Manager | G8: 44424 | H8: 3 - 5 Years | I8: 1 year(s), 8 month(s), 16 day(s) | J8: Strong | K8: Solid | L8: Medium | M8: Medium | N8: {=IF(OR(L8="",M8=""),"", IF(OR(ISNA(MATCH(L8,{"Low","Medium","High"},0)), ISNA(MATCH(M8,{"Low","Medium","High"},0))),"",_xlfn.SWITCH(L8,"Low",1,"Medium",2,"High",3) + 3 * _xlfn.SWITCH(M8,"Low",1,"Medium",2,"High",3) - 3))} -> 5 | O8: 5. Core Talent | P8: =IFERROR(VLOOKUP(O8,'Excel Table (Do Not Format)'!A:D,2,FALSE),"") -> Core Talent [M,M] | Q8: =IFERROR(VLOOKUP(O8,'Excel Table (Do Not Format)'!A:D,3,FALSE),"") -> identify performance barriers, explore portential to expand responsibilties in current role and discuss career aspirations (ideally for talent new in role) | R8: =IFERROR(VLOOKUP(O8,'Excel Table (Do Not Format)'!A:D,4,FALSE),"") -> Develop in Role - Identify developmental activities to continue to grow their skill and set them up for success for anticiapted progression | S8: Katie's shown improvement in performance with her more focused role in the new pillar system. She's effectively setting and communicating goals, actively managing performance, and eagerly embracing organizational changes. | T8: No | U8: Elizabeth Benker | V8: Elizabeth Benker
A9: 1966 | B9: Lindsey Zibell | C9: Sr. Dir, Product Management-USA | D9: Sr. Dir, Product Management-USA | E9: Sr. Dir, Product Management-USA | F9: MT6 - Sr. Director | G9: 43108 | H9: 5 - 10 Years | I9: 0 year(s), 8 month(s), 17 day(s) | J9: Leading | K9: Leading | L9: Medium | M9: High | N9: {=IF(OR(L9="",M9=""),"", IF(OR(ISNA(MATCH(L9,{"Low","Medium","High"},0)), ISNA(MATCH(M9,{"Low","Medium","High"},0))),"",_xlfn.SWITCH(L9,"Low",1,"Medium",2,"High",3) + 3 * _xlfn.SWITCH(M9,"Low",1,"Medium",2,"High",3) - 3))} -> 8 | O9: 5. Core Talent | P9: =IFERROR(VLOOKUP(O9,'Excel Table (Do Not Format)'!A:D,2,FALSE),"") -> Core Talent [M,M] | Q9: =IFERROR(VLOOKUP(O9,'Excel Table (Do Not Format)'!A:D,3,FALSE),"") -> identify performance barriers, explore portential to expand responsibilties in current role and discuss career aspirations (ideally for talent new in role) | R9: =IFERROR(VLOOKUP(O9,'Excel Table (Do Not Format)'!A:D,4,FALSE),"") -> Develop in Role - Identify developmental activities to continue to grow their skill and set them up for success for anticiapted progression | U9: Laura Williams Argilla | V9: Laura Williams Argilla
A10: 101909 | B10: Marcela Abrach | C10: Sr. Manager, Global Content | D10: Sr. Mgr, Technical Writing-USA | E10: Sr. Mgr, Technical Writing-USA | F10: MT3 - Sr. Manager | G10: 44319 | H10: 3 - 5 Years | I10: 3 year(s), 4 month(s), 18 day(s) | J10: Strong | K10: Strong | L10: Low | M10: Medium | N10: {=IF(OR(L10="",M10=""),"", IF(OR(ISNA(MATCH(L10,{"Low","Medium","High"},0)), ISNA(MATCH(M10,{"Low","Medium","High"},0))),"",_xlfn.SWITCH(L10,"Low",1,"Medium",2,"High",3) + 3 * _xlfn.SWITCH(M10,"Low",1,"Medium",2,"High",3) - 3))} -> 4 | O10: 4. Inconsistent Talent | P10: =IFERROR(VLOOKUP(O10,'Excel Table (Do Not Format)'!A:D,2,FALSE),"") -> Inconsistent Talent [L,M] | Q10: =IFERROR(VLOOKUP(O10,'Excel Table (Do Not Format)'!A:D,3,FALSE),"") -> re-establish performance expectations in current role, drive performance and re-evaluate in 6-12 months | R10: =IFERROR(VLOOKUP(O10,'Excel Table (Do Not Format)'!A:D,4,FALSE),"") -> Evaluate Fit/Make A Plan - Identify a coaching plan to improve performance | S10: Marcella has moved to a different role, effective in January. This move will be more suited to her strengths. I anticipate her Talent Indicator to improve as she settles into the new role. | T10: No | U10: Elizabeth Benker | V10: Elizabeth Benker
A11: 103572 | B11: Nicole Johnson | C11: Dir, Product Management | D11: Dir, Product Management-USA | E11: Dir, Product Management-USA | F11: MT5 - Director | G11: 44676 | H11: 3 - 5 Years | I11: 0 year(s), 2 month(s), 18 day(s) | J11: Strong | K11: Leading | L11: Medium | M11: High | N11: {=IF(OR(L11="",M11=""),"", IF(OR(ISNA(MATCH(L11,{"Low","Medium","High"},0)), ISNA(MATCH(M11,{"Low","Medium","High"},0))),"",_xlfn.SWITCH(L11,"Low",1,"Medium",2,"High",3) + 3 * _xlfn.SWITCH(M11,"Low",1,"Medium",2,"High",3) - 3))} -> 8 | O11: 5. Core Talent | P11: =IFERROR(VLOOKUP(O11,'Excel Table (Do Not Format)'!A:D,2,FALSE),"") -> Core Talent [M,M] | Q11: =IFERROR(VLOOKUP(O11,'Excel Table (Do Not Format)'!A:D,3,FALSE),"") -> identify performance barriers, explore portential to expand responsibilties in current role and discuss career aspirations (ideally for talent new in role) | R11: =IFERROR(VLOOKUP(O11,'Excel Table (Do Not Format)'!A:D,4,FALSE),"") -> Develop in Role - Identify developmental activities to continue to grow their skill and set them up for success for anticiapted progression | U11: Laura Williams Argilla | V11: Laura Williams Argilla
A12: 101687 | B12: Olga Ziegelman | C12: Sr. Manager, UX Research | D12: Sr. Mgr, UI/UX Research-USA | E12: Sr. Mgr, UI/UX Research-USA | F12: MT3 - Sr. Manager | G12: 44256 | H12: 3 - 5 Years | I12: 1 year(s), 8 month(s), 16 day(s) | J12: Leading | K12: Strong | L12: Medium | M12: Medium | N12: {=IF(OR(L12="",M12=""),"", IF(OR(ISNA(MATCH(L12,{"Low","Medium","High"},0)), ISNA(MATCH(M12,{"Low","Medium","High"},0))),"",_xlfn.SWITCH(L12,"Low",1,"Medium",2,"High",3) + 3 * _xlfn.SWITCH(M12,"Low",1,"Medium",2,"High",3) - 3))} -> 5 | O12: 5. Core Talent | P12: =IFERROR(VLOOKUP(O12,'Excel Table (Do Not Format)'!A:D,2,FALSE),"") -> Core Talent [M,M] | Q12: =IFERROR(VLOOKUP(O12,'Excel Table (Do Not Format)'!A:D,3,FALSE),"") -> identify performance barriers, explore portential to expand responsibilties in current role and discuss career aspirations (ideally for talent new in role) | R12: =IFERROR(VLOOKUP(O12,'Excel Table (Do Not Format)'!A:D,4,FALSE),"") -> Develop in Role - Identify developmental activities to continue to grow their skill and set them up for success for anticiapted progression | S12: No change from last time. With Erin Howard now in place, Olga will have an opportunity to shift her team to be more part of the Customer Signals org remit, and will benefit from learning new methods and approaches. | T12: No | U12: Erin Howard | V12: Elizabeth Benker | W12: Erin Howard
A13: 101023 | B13: Pavla Miksova (On Leave) | C13: Mgr, UI/UX Design-CZE | D13: Mgr, UI/UX Design-CZE | E13: Mgr, UI/UX Design-CZE | F13: MT2 - Manager | G13: 43843 | H13: 5 - 10 Years | I13: 2 year(s), 8 month(s), 18 day(s) | J13: Strong | K13: Strong | L13: Medium | M13: Medium | N13: {=IF(OR(L13="",M13=""),"", IF(OR(ISNA(MATCH(L13,{"Low","Medium","High"},0)), ISNA(MATCH(M13,{"Low","Medium","High"},0))),"",_xlfn.SWITCH(L13,"Low",1,"Medium",2,"High",3) + 3 * _xlfn.SWITCH(M13,"Low",1,"Medium",2,"High",3) - 3))} -> 5 | O13: 5. Core Talent | P13: =IFERROR(VLOOKUP(O13,'Excel Table (Do Not Format)'!A:D,2,FALSE),"") -> Core Talent [M,M] | Q13: =IFERROR(VLOOKUP(O13,'Excel Table (Do Not Format)'!A:D,3,FALSE),"") -> identify performance barriers, explore portential to expand responsibilties in current role and discuss career aspirations (ideally for talent new in role) | R13: =IFERROR(VLOOKUP(O13,'Excel Table (Do Not Format)'!A:D,4,FALSE),"") -> Develop in Role - Identify developmental activities to continue to grow their skill and set them up for success for anticiapted progression | S13: No change - has been on leave this entire year | T13: No | U13: Elizabeth Benker | V13: Elizabeth Benker
A14: 102014 | B14: Rachel Howard | C14: Dir, Product Management | D14: Dir, Product Management-USA | E14: Dir, Product Management-USA | F14: MT5 - Director | G14: 44340 | H14: 3 - 5 Years | I14: 0 year(s), 8 month(s), 17 day(s) | J14: Solid | K14: Strong | L14: Medium | M14: High | N14: {=IF(OR(L14="",M14=""),"", IF(OR(ISNA(MATCH(L14,{"Low","Medium","High"},0)), ISNA(MATCH(M14,{"Low","Medium","High"},0))),"",_xlfn.SWITCH(L14,"Low",1,"Medium",2,"High",3) + 3 * _xlfn.SWITCH(M14,"Low",1,"Medium",2,"High",3) - 3))} -> 8 | O14: 5. Core Talent | P14: =IFERROR(VLOOKUP(O14,'Excel Table (Do Not Format)'!A:D,2,FALSE),"") -> Core Talent [M,M] | Q14: =IFERROR(VLOOKUP(O14,'Excel Table (Do Not Format)'!A:D,3,FALSE),"") -> identify performance barriers, explore portential to expand responsibilties in current role and discuss career aspirations (ideally for talent new in role) | R14: =IFERROR(VLOOKUP(O14,'Excel Table (Do Not Format)'!A:D,4,FALSE),"") -> Develop in Role - Identify developmental activities to continue to grow their skill and set them up for success for anticiapted progression | U14: Laura Williams Argilla | V14: Laura Williams Argilla
A15: 102692 | B15: Robert D'Arrigo | C15: Sr. Director, Product Management | D15: Sr. Dir, Product Management-AUS | E15: Sr. Dir, Product Management-AUS | F15: MT6 - Sr. Director | G15: 44476 | H15: 5 - 10 Years | I15: 1 year(s), 8 month(s), 18 day(s) | J15: Strong | K15: Leading | L15: High | M15: High | N15: {=IF(OR(L15="",M15=""),"", IF(OR(ISNA(MATCH(L15,{"Low","Medium","High"},0)), ISNA(MATCH(M15,{"Low","Medium","High"},0))),"",_xlfn.SWITCH(L15,"Low",1,"Medium",2,"High",3) + 3 * _xlfn.SWITCH(M15,"Low",1,"Medium",2,"High",3) - 3))} -> 9 | O15: 9.Top Talent | P15: =IFERROR(VLOOKUP(O15,'Excel Table (Do Not Format)'!A:D,2,FALSE),"") -> Top Talent [H,H] | Q15: =IFERROR(VLOOKUP(O15,'Excel Table (Do Not Format)'!A:D,3,FALSE),"") -> identify stretch experiences or temporary assignments, increase executive exposure | R15: =IFERROR(VLOOKUP(O15,'Excel Table (Do Not Format)'!A:D,4,FALSE),"") -> Differentially Invest - Ensure career discussions are happening regularly? Do they have an individual development plan? What opportunities exist to accelerate development and growth? Revisit talent often to plan for next steps. | U15: Chad Thompson | V15: Chad Thompson
A16: 106415 | B16: Tomáš Mitana | C16: Sr. Director, Product Management - Data & Connectivity | D16: Sr. Dir, Product Management-CZE | E16: Sr. Dir, Product Management-CZE | F16: MT6 - Sr. Director | G16: 45971 | H16: 0 - 3 Months | I16: 0 year(s), 0 month(s), 9 day(s) | O16: 5. Core Talent | P16: =IFERROR(VLOOKUP(O16,'Excel Table (Do Not Format)'!A:D,2,FALSE),"") -> Core Talent [M,M] | Q16: =IFERROR(VLOOKUP(O16,'Excel Table (Do Not Format)'!A:D,3,FALSE),"") -> identify performance barriers, explore portential to expand responsibilties in current role and discuss career aspirations (ideally for talent new in role) | R16: =IFERROR(VLOOKUP(O16,'Excel Table (Do Not Format)'!A:D,4,FALSE),"") -> Develop in Role - Identify developmental activities to continue to grow their skill and set them up for success for anticiapted progression | U16: Chad Thompson | V16: Chad Thompson
A17: 102693 | B17: Will Hurley | C17: Sr. Mgr, UX/UI Design | D17: Sr. Mgr, UX/UI Design | E17: Sr. Mgr, UI/UX Design-AUS | F17: MT3 - Sr. Manager | G17: 44476 | H17: 5 - 10 Years | I17: 4 year(s), 1 month(s), 12 day(s) | J17: Strong | K17: Strong | L17: High | M17: High | N17: {=IF(OR(L17="",M17=""),"", IF(OR(ISNA(MATCH(L17,{"Low","Medium","High"},0)), ISNA(MATCH(M17,{"Low","Medium","High"},0))),"",_xlfn.SWITCH(L17,"Low",1,"Medium",2,"High",3) + 3 * _xlfn.SWITCH(M17,"Low",1,"Medium",2,"High",3) - 3))} -> 9 | O17: 9.Top Talent | P17: =IFERROR(VLOOKUP(O17,'Excel Table (Do Not Format)'!A:D,2,FALSE),"") -> Top Talent [H,H] | Q17: =IFERROR(VLOOKUP(O17,'Excel Table (Do Not Format)'!A:D,3,FALSE),"") -> identify stretch experiences or temporary assignments, increase executive exposure | R17: =IFERROR(VLOOKUP(O17,'Excel Table (Do Not Format)'!A:D,4,FALSE),"") -> Differentially Invest - Ensure career discussions are happening regularly? Do they have an individual development plan? What opportunities exist to accelerate development and growth? Revisit talent often to plan for next steps. | S17: We've already discussed promoting Will to Director; strongly support this move. | T17: Yes | U17: Elizabeth Benker | V17: Elizabeth Benker
A18: 103412 | B18: Yujia Zhao | C18: Mgr, UI/UX Design | D18: Mgr, UI/UX Design-USA | E18: Mgr, UI/UX Design-USA | F18: MT2 - Manager | G18: 44599 | H18: 3 - 5 Years | I18: 0 year(s), 2 month(s), 18 day(s) | J18: Strong | K18: Strong | L18: High | M18: High | N18: {=IF(OR(L18="",M18=""),"", IF(OR(ISNA(MATCH(L18,{"Low","Medium","High"},0)), ISNA(MATCH(M18,{"Low","Medium","High"},0))),"",_xlfn.SWITCH(L18,"Low",1,"Medium",2,"High",3) + 3 * _xlfn.SWITCH(M18,"Low",1,"Medium",2,"High",3) - 3))} -> 9 | O18: 8. Growth Talent | P18: =IFERROR(VLOOKUP(O18,'Excel Table (Do Not Format)'!A:D,2,FALSE),"") -> Growth Talent [M,H] | Q18: =IFERROR(VLOOKUP(O18,'Excel Table (Do Not Format)'!A:D,3,FALSE),"") -> identify performance barriers, explore portential to expand responsibilties in current role | R18: =IFERROR(VLOOKUP(O18,'Excel Table (Do Not Format)'!A:D,4,FALSE),"") -> Differentially Invest - Ensure career discussions are happening regularly? Do they have an individual development plan? What opportunities exist to accelerate development and growth? Revisit talent often to plan for next steps. | S18: Seeing signs of stress as she assumes larger team and higher level of responsibility. Needs continued coaching on navigating political challenges. | T18: No | U18: Elizabeth Benker | V18: Elizabeth Benker
A19: 104467 | B19: Patrik Volek | C19: Interim Manager UX/UI Design | D19: Advanced Professional, UI/UX Designer-CZE | E19: Advanced Professional, UI/UX Designer-CZE | F19: PT4 - Advanced Professional | G19: 44866 | H19: 2 - 3 Years | I19: 1 year(s), 2 month(s), 18 day(s) | J19: Strong | K19: Solid | L19: Medium | M19: Medium | N19: 5 | O19: 8. Growth Talent | P19: Core Talent [M,M] | Q19: identify performance barriers, explore portential to expand responsibilties in current role and discuss career aspirations (ideally for talent new in role) | R19: Develop in Role - Identify developmental activities to continue to grow their skill and set them up for success for anticiapted progression | S19: First cycle as manager; strong early performance indicators. Needs coaching in proactively raising POV and navigating political challenges. | T19: No | U19: Elizabeth Benker | V19: Elizabeth Benker

Sheet Pivot
A1: Talent Mapping Position [Performance vs Potential] | B1: (All)
A3: 9- Box Calibration | B3: Count of Worker | C3: Percent | E3: Count of Worker
A4: 1. Underperforming Talent | B4: 2 | C4: 0.017391304 | E4: Talent Mapping Position [Performance vs Potential] | F4: Worker | G4: Total
A5: 2. Solid Talent | B5: 7 | C5: 0.060869565 | E5: Core Talent [M,M] | F5: Apurva Mathur | G5: 1
A6: 3. Expert Talent | B6: 3 | C6: 0.026086957 | F6: ARPIT VERMA | G6: 1
A7: 4. Inconsistent Talent | B7: 7 | C7: 0.060869565 | F7: Artem Pakhomov (Артём Пахомов) | G7: 1
A8: 5. Core Talent | B8: 62 | C8: 0.53913043 | F8: Ashutosh Kumar | G8: 1
A9: 6.High Impact Talent | B9: 10 | C9: 0.086956522 | F9: Baneen Bryan | G9: 1
A10: 8. Growth Talent | B10: 8 | C10: 0.069565217 | F10: Bob Fraser | G10: 1
A11: 9.Top Talent | B11: 16 | C11: 0.13913043 | F11: Chad Thompson | G11: 1
A12: Grand Total | B12: 115 | C12: 1 | F12: David Domagalski | G12: 1
F13: Elizabeth Benker | G13: 1
F14: Elizabeth Cardinal | G14: 1
F15: Erin Howard | G15: 1
F16: Francois Planet | G16: 1
F17: Gabe Keaveney | G17: 1
F18: Gayatri Kakarlapudi | G18: 1
F19: Geoffrey Zath | G19: 1
F20: Gita Ligure | G20: 1
F21: Greg Filla (On Leave) | G21: 1
F22: HEMANTI PRADHAN | G22: 1
F23: Jarrod Thuener | G23: 1
F24: Jay Shipley | G24: 1
... F66: Xenija Podjablonskaja (On Leave) | G66: 1
E67: Core Talent [M,M] Total | G67: 62
E68: Expert Talent [H,L] | F68: Adriana Rybarova | G68: 1
F69: Ani Worlikar | G69: 1
F70: Elad Idan | G70: 1
E71: Expert Talent [H,L] Total | G71: 3
E72: Growth Talent [M,H] | F72: Alexandra Zelinskaya | G72: 1
F73: Dhiraj Sahu | G73: 1
F74: Jinju Hopkins (On Leave) | G74: 1
F75: Lindsey Zibell | G75: 1
F76: Nicole Johnson | G76: 1
F77: Peter Ott | G77: 1
F78: Rachel Howard | G78: 1
F79: Raffaela Bethke | G79: 1
E80: Growth Talent [M,H] Total | G80: 8
E81: High Impact Talent [H,M] | F81: Agnimitra Pathak | G81: 1
F82: Aida Abbasi | G82: 1
...

Sheet Excel Table (Do Not Format)
A1: FY25 Talent Indicator | B1: Talent Mapping Position | C1: Development Focus | D1: Development Action
A2: 7. Emerging Talent/ Off-Track | B2: Emerging Talent/ Off-Track [L,H] | C2: drive performance in current role and re-evaluate in 6-12 months | D2: Evaluate Fit - What is causing them to underperform? Are they in the right role? Do they need a mentor and/or additional guidance?
A3: 4. Inconsistent Talent | B3: Inconsistent Talent [L,M] | C3: re-establish performance expectations in current role, drive performance and re-evaluate in 6-12 months | D3: Evaluate Fit/Make A Plan - Identify a coaching plan to improve performance
A4: 1. Underperforming Talent | B4: Underperforming Talent [L,L] | C4: re-assign or manage out of Alteryx | D4: Make A Plan - Identify a plan to improve performance in partnership with HR
A5: 8. Growth Talent | B5: Growth Talent [M,H] | C5: identify performance barriers, explore portential to expand responsibilties in current role | D5: Differentially Invest - Ensure career discussions are happening regularly? Do they have an individual development plan? What opportunities exist to accelerate development and growth? Revisit talent often to plan for next steps.
A6: 5. Core Talent | B6: Core Talent [M,M] | C6: identify performance barriers, explore portential to expand responsibilties in current role and discuss career aspirations (ideally for talent new in role) | D6: Develop in Role - Identify developmental activities to continue to grow their skill and set them up for success for anticiapted progression
A7: 2. Solid Talent | B7: Solid Talent [M,L] | C7: consider expanding current role, explore lateral/development opportunities | D7: Develop in Role - Identify developmental activities to continue to grow their skill and set them up for success for anticiapted progression
A8: 9.Top Talent | B8: Top Talent [H,H] | C8: identify stretch experiences or temporary assignments, increase executive exposure | D8: Differentially Invest - Ensure career discussions are happening regularly? Do they have an individual development plan? What opportunities exist to accelerate development and growth? Revisit talent often to plan for next steps.
A9: 6.High Impact Talent | B9: High Impact Talent [H,M] | C9: expand responsibilities in current role, identify key experiences and increase executive exposure | D9: Differentially Invest - Ensure career discussions are happening regularly? Do they have an individual development plan? What opportunities exist to accelerate development and growth? Revisit talent often to plan for next steps.
A10: 3. Expert Talent | B10: Expert Talent [H,L] | C10: leverage experience to mentor and growth others | D10: Develop in Role - Identify developmental activities to continue to grow their skill and set them up for success for anticiapted progression
